Workbook

Sheet Listado
A1: IdJanij | B1: Nombre | C1: NumSocio | D1: FechaNacimiento | E1: DNI | F1: MailJanij | G1: TeléfonoJanij | H1: Adulto1 | I1: MailAdulto1 | J1: TelAdulto1 | K1: Adulto2 | L1: MailAdulto2 | M1: TelAdulto2 | N1: Colegio | O1: HermanxsJuventud | P1: ActividadesCISSAB | Q1: JashiNeda | R1: Alimentacion | S1: Color | T1: Mejan | V1: Asistencia Promedio
A2: 170 | B2: Victoria Mizrahi | C2: 1077302 | D2: 40065 | E2: 49700884 | F2: mizrahivictoria09@gmail.com | G2: 1165785831 | H2: Valeria Bulgach | I2: valebulg@gmail.com | J2: 1154900991 | K2: David mizrahi | L2: davidurielmizrahi@gmail.com | M2: 1131989670 | N2: ort | O2: hermana en bogrim mayor | P2: fútbol femenino | Q2: Nedarim | R2: Sin restricciones | S2: AZUL | T2: =IFS(SUM(IFNA(MATCH($B2,'DIVISION 15'!$A$2:$H$2,0),""),IFNA(MATCH($B2,'DIVISION 15'!$A$3:$H$3,0),""),IFNA(MATCH($B2,'DIVISION 15'!$A$4:$H$4,0),""),IFNA(MATCH($B2,'DIVISION 15'!$A$5:$H$5,0),""),IFNA(MATCH($B2,'DIVISION 15'!$A$6:$H$6,0),""),IFNA(MATCH($B2,'DIVISION 15'!$A$7:$H$7,0),""),IFNA(MATCH($B2,'DIVISION 15'!$A$8:$H$8,0),""),IFNA(MATCH($B2,'DIVISION 15'!$A$9:$H$9,0),""),IFNA(MATCH($B2,'DIVISION 15'!$A$10:$H$10,0),""),IFNA(MATCH($B2,'DIVISION 15'!$A$11:$H$11,0),""),IFNA(MATCH($B2,'DIVISION 15'!$A$12:$H$12,0),""),IFNA(MATCH($B2,'DIVISION 15'!$A$13:$H$13,0),""),IFNA(MATCH($B2,'DIVISION 15'!$A$14:$H$14,0),""),IFNA(MATCH($B2,'DIVISION 15'!$A$15:$H$15,0),""),IFNA(MATCH($B2,'DIVISION 15'!$A$16:$H$16,0),""),IFNA(MATCH($B2,'DIVISION 15'!$A$17:$H$17,0),""),IFNA(MATCH($B2,'DIVISION 15'!$A$18:$H$18,0),""))=1,'DIVISION 15'!$A$1,SUM(IFNA(MATCH($B2,'DIVISION 15'!$A$2:$H$2,0),""),IFNA(MATCH($B2,'DIVISION 15'!$A$3:$H$3,0),""),IFNA(MATCH($B2,'DIVISION 15'!$A$4:$H$4,0),""),IFNA(MATCH($B2,'DIVISION 15'!$A$5:$H$5,0),""),IFNA(MATCH($B2,'DIVISION 15'!$A$6:$H$6,0),""),IFNA(MATCH($B2,'DIVISION 15'!$A$7:$H$7,0),""),IFNA(MATCH($B2,'DIVISION 15'!$A$8:$H$8,0),""),IFNA(MATCH($B2,'DIVISION 15'!$A$9:$H$9,0),""),IFNA(MATCH($B2,'DIVISION 15'!$A$10:$H$10,0),""),IFNA(MATCH($B2,'DIVISION 15'!$A$11:$H$11,0),""),IFNA(MATCH($B2,'DIVISION 15'!$A$12:$H$12,0),""),IFNA(MATCH($B2,'DIVISION 15'!$A$13:$H$13,0),""),IFNA(MATCH($B2,'DIVISION 15'!$A$14:$H$14,0),""),IFNA(MATCH($B2,'DIVISION 15'!$A$15:$H$15,0),""),IFNA(MATCH($B2,'DIVISION 15'!$A$16:$H$16,0),""),IFNA(MATCH($B2,'DIVISION 15'!$A$17:$H$17,0),""),IFNA(MATCH($B2,'DIVISION 15'!$A$18:$H$18,0),""))=2,'DIVISION 15'!$B$1,SUM(IFNA(MATCH($B2,'DIVISION 15'!$A$2:$H$2,0),""),IFNA(MATCH($B2,'DIVISION 15'!$A$3:$H$3,0),""),IFNA(MATCH($B2,'DIVISION 15'!$A$4:$H$4,0),""),IFNA(MATCH($B2,'DIVISION 15'!$A$5:$H$5,0),""),IFNA(MATCH($B2,'DIVISION 15'!$A$6:$H$6,0),""),IFNA(MATCH($B2,'DIVISION 15'!$A$7:$H$7,0),""),IFNA(MATCH($B2,'DIVISION 15'!$A$8:$H$8,0),""),IFNA(MATCH($B2,'DIVISION 15'!$A$9:$H$9,0),""),IFNA(MATCH($B2,'DIVISION 15'!$A$10:$H$10,0),""),IFNA(MATCH($B2,'DIVISION 15'!$A$11:$H$11,0),""),IFNA(MATCH($B2,'DIVISION 15'!$A$12:$H$12,0),""),IFNA(MATCH($B2,'DIVISION 15'!$A$13:$H$13,0),""),IFNA(MATCH($B2,'DIVISION 15'!$A$14:$H$14,0),""),IFNA(MATCH($B2,'DIVISION 15'!$A$15:$H$15,0),""),IFNA(MATCH($B2,'DIVISION 15'!$A$16:$H$16,0),""),IFNA(MATCH($B2,'DIVISION 15'!$A$17:$H$17,0),""),IFNA(MATCH($B2,'DIVISION 15'!$A$18:$H$18,0),""))=3,'DIVISION 15'!$C$1,SUM(IFNA(MATCH($B2,'DIVISION 15'!$A$2:$H$2,0),""),IFNA(MATCH($B2,'DIVISION 15'!$A$3:$H$3,0),""),IFNA(MATCH($B2,'DIVISION 15'!$A$4:$H$4,0),""),IFNA(MATCH($B2,'DIVISION 15'!$A$5:$H$5,0),""),IFNA(MATCH($B2,'DIVISION 15'!$A$6:$H$6,0),""),IFNA(MATCH($B2,'DIVISION 15'!$A$7:$H$7,0),""),IFNA(MATCH($B2,'DIVISION 15'!$A$8:$H$8,0),""),IFNA(MATCH($B2,'DIVISION 15'!$A$9:$H$9,0),""),IFNA(MATCH($B2,'DIVISION 15'!$A$10:$H$10,0),""),IFNA(MATCH($B2,'DIVISION 15'!$A$11:$H$11,0),""),IFNA(MATCH($B2,'DIVISION 15'!$A$12:$H$12,0),""),IFNA(MATCH($B2,'DIVISION 15'!$A$13:$H$13,0),""),IFNA(MATCH($B2,'DIVISION 15'!$A$14:$H$14,0),""),IFNA(MATCH($B2,'DIVISION 15'!$A$15:$H$15,0),""),IFNA(MATCH($B2,'DIVISION 15'!$A$16:$H$16,0),""),IFNA(MATCH($B2,'DIVISION 15'!$A$17:$H$17,0),""),IFNA(MATCH($B2,'DIVISION 15'!$A$18:$H$18,0),""))=4,'DIVISION 15'!$D$1,SUM(IFNA(MATCH($B2,'DIVISION 15'!$A$2:$H$2,0),""),IFNA(MATCH($B2,'DIVISION 15'!$A$3:$H$3,0),""),IFNA(MATCH($B2,'DIVISION 15'!$A$4:$H$4,0),""),IFNA(MATCH($B2,'DIVISION 15'!$A$5:$H$5,0),""),IFNA(MATCH($B2,'DIVISION 15'!$A$6:$H$6,0),""),IFNA(MATCH($B2,'DIVISION 15'!$A$7:$H$7,0),""),IFNA(MATCH($B2,'DIVISION 15'!$A$8:$H$8,0),""),IFNA(MATCH($B2,'DIVISION 15'!$A$9:$H$9,0),""),IFNA(MATCH($B2,'DIVISION 15'!$A$10:$H$10,0),""),IFNA(MATCH($B2,'DIVISION 15'!$A$11:$H$11,0),""),IFNA(MATCH($B2,'DIVISION 15'!$A$12:$H$12,0),""),IFNA(MATCH($B2,'DIVISION 15'!$A$13:$H$13,0),""),IFNA(MATCH($B2,'DIVISION 15'!$A$14:$H$14,0),""),IFNA(MATCH($B2,'DIVISION 15'!$A$15:$H$15,0),""),IFNA(MATCH($B2,'DIVISION 15'!$A$16:$H$16,0),""),IFNA(MATCH($B2,'DIVISION 15'!$A$17:$H$17,0),""),IFNA(MATCH($B2,'DIVISION 15'!$A$18:$H$18,0),""))=5,'DIVISION 15'!$E$1,SUM(IFNA(MATCH($B2,'DIVISION 15'!$A$2:$H$2,0),""),IFNA(MATCH($B2,'DIVISION 15'!$A$3:$H$3,0),""),IFNA(MATCH($B2,'DIVISION 15'!$A$4:$H$4,0),""),IFNA(MATCH($B2,'DIVISION 15'!$A$5:$H$5,0),""),IFNA(MATCH($B2,'DIVISION 15'!$A$6:$H$6,0),""),IFNA(MATCH($B2,'DIVISION 15'!$A$7:$H$7,0),""),IFNA(MATCH($B2,'DIVISION 15'!$A$8:$H$8,0),""),IFNA(MATCH($B2,'DIVISION 15'!$A$9:$H$9,0),""),IFNA(MATCH($B2,'DIVISION 15'!$A$10:$H$10,0),""),IFNA(MATCH($B2,'DIVISION 15'!$A$11:$H$11,0),""),IFNA(MATCH($B2,'DIVISION 15'!$A$12:$H$12,0),""),IFNA(MATCH($B2,'DIVISION 15'!$A$13:$H$13,0),""),IFNA(MATCH($B2,'DIVISION 15'!$A$14:$H$14,0),""),IFNA(MATCH($B2,'DIVISION 15'!$A$15:$H$15,0),""),IFNA(MATCH($B2,'DIVISION 15'!$A$16:$H$16,0),""),IFNA(MATCH($B2,'DIVISION 15'!$A$17:$H$17,0),""),IFNA(MATCH($B2,'DIVISION 15'!$A$18:$H$18,0),""))=6,'DIVISION 15'!$F$1,SUM(IFNA(MATCH($B2,'DIVISION 15'!$A$2:$H$2,0),""),IFNA(MATCH($B2,'DIVISION 15'!$A$3:$H$3,0),""),IFNA(MATCH($B2,'DIVISION 15'!$A$4:$H$4,0),""),IFNA(MATCH($B2,'DIVISION 15'!$A$5:$H$5,0),""),IFNA(MATCH($B2,'DIVISION 15'!$A$6:$H$6,0),""),IFNA(MATCH($B2,'DIVISION 15'!$A$7:$H$7,0),""),IFNA(MATCH($B2,'DIVISION 15'!$A$8:$H$8,0),""),IFNA(MATCH($B2,'DIVISION 15'!$A$9:$H$9,0),""),IFNA(MATCH($B2,'DIVISION 15'!$A$10:$H$10,0),""),IFNA(MATCH($B2,'DIVISION 15'!$A$11:$H$11,0),""),IFNA(MATCH($B2,'DIVISION 15'!$A$12:$H$12,0),""),IFNA(MATCH($B2,'DIVISION 15'!$A$13:$H$13,0),""),IFNA(MATCH($B2,'DIVISION 15'!$A$14:$H$14,0),""),IFNA(MATCH($B2,'DIVISION 15'!$A$15:$H$15,0),""),IFNA(MATCH($B2,'DIVISION 15'!$A$16:$H$16,0),""),IFNA(MATCH($B2,'DIVISION 15'!$A$17:$H$17,0),""),IFNA(MATCH($B2,'DIVISION 15'!$A$18:$H$18,0),""))=7,'DIVISION 15'!$G$1,SUM(IFNA(MATCH($B2,'DIVISION 15'!$A$2:$H$2,0),""),IFNA(MATCH($B2,'DIVISION 15'!$A$3:$H$3,0),""),IFNA(MATCH($B2,'DIVISION 15'!$A$4:$H$4,0),""),IFNA(MATCH($B2,'DIVISION 15'!$A$5:$H$5,0),""),IFNA(MATCH($B2,'DIVISION 15'!$A$6:$H$6,0),""),IFNA(MATCH($B2,'DIVISION 15'!$A$7:$H$7,0),""),IFNA(MATCH($B2,'DIVISION 15'!$A$8:$H$8,0),""),IFNA(MATCH($B2,'DIVISION 15'!$A$9:$H$9,0),""),IFNA(MATCH($B2,'DIVISION 15'!$A$10:$H$10,0),""),IFNA(MATCH($B2,'DIVISION 15'!$A$11:$H$11,0),""),IFNA(MATCH($B2,'DIVISION 15'!$A$12:$H$12,0),""),IFNA(MATCH($B2,'DIVISION 15'!$A$13:$H$13,0),""),IFNA(MATCH($B2,'DIVISION 15'!$A$14:$H$14,0),""),IFNA(MATCH($B2,'DIVISION 15'!$A$15:$H$15,0),""),IFNA(MATCH($B2,'DIVISION 15'!$A$16:$H$16,0),""),IFNA(MATCH($B2,'DIVISION 15'!$A$17:$H$17,0),""),IFNA(MATCH($B2,'DIVISION 15'!$A$18:$H$18,0),""))=8,'DIVISION 15'!$H$1) -> LULI | U2: =T2&COUNTIF($T$1:T2,T2) -> LULI1 | V2: =SUMIF(AsistenciaViewJetAdmin!$A$3:$A$101,A2,AsistenciaViewJetAdmin!$C$3:$C$101)/(COUNTIF(AsistenciaViewJetAdmin!$D$102:V$102,">0")+COUNTIF(ActividadesEspeciales!$D$102:V$102,">0"))*100 -> 57.978723
A3: 134 | B3: Vera Kaplan | C3: 69312 | D3: 23122009 | E3: 50031430 | F3: 50031430@est.ort.edu.ar | G3: 1167004882 | H3: Adrian Kaplan | I3: adrokaplan@yahoo.com.ar | J3: 1131751107 | K3: Juliana gil gomez | L3: julianagilgomez@gmail.com | M3: 112472-0628 | N3: Ort yatay | O3: Galo madrij. | P3: Hockey | Q3: Nedarim | S3: NARANJA | T3: =IFS(SUM(IFNA(MATCH($B3,'DIVISION 15'!$A$2:$H$2,0),""),IFNA(MATCH($B3,'DIVISION 15'!$A$3:$H$3,0),""),IFNA(MATCH($B3,'DIVISION 15'!$A$4:$H$4,0),""),IFNA(MATCH($B3,'DIVISION 15'!$A$5:$H$5,0),""),IFNA(MATCH($B3,'DIVISION 15'!$A$6:$H$6,0),""),IFNA(MATCH($B3,'DIVISION 15'!$A$7:$H$7,0),""),IFNA(MATCH($B3,'DIVISION 15'!$A$8:$H$8,0),""),IFNA(MATCH($B3,'DIVISION 15'!$A$9:$H$9,0),""),IFNA(MATCH($B3,'DIVISION 15'!$A$10:$H$10,0),""),IFNA(MATCH($B3,'DIVISION 15'!$A$11:$H$11,0),""),IFNA(MATCH($B3,'DIVISION 15'!$A$12:$H$12,0),""),IFNA(MATCH($B3,'DIVISION 15'!$A$13:$H$13,0),""),IFNA(MATCH($B3,'DIVISION 15'!$A$14:$H$14,0),""),IFNA(MATCH($B3,'DIVISION 15'!$A$15:$H$15,0),""),IFNA(MATCH($B3,'DIVISION 15'!$A$16:$H$16,0),""),IFNA(MATCH($B3,'DIVISION 15'!$A$17:$H$17,0),""),IFNA(MATCH($B3,'DIVISION 15'!$A$18:$H$18,0),""))=1,'DIVISION 15'!$A$1,SUM(IFNA(MATCH($B3,'DIVISION 15'!$A$2:$H$2,0),""),IFNA(MATCH($B3,'DIVISION 15'!$A$3:$H$3,0),""),IFNA(MATCH($B3,'DIVISION 15'!$A$4:$H$4,0),""),IFNA(MATCH($B3,'DIVISION 15'!$A$5:$H$5,0),""),IFNA(MATCH($B3,'DIVISION 15'!$A$6:$H$6,0),""),IFNA(MATCH($B3,'DIVISION 15'!$A$7:$H$7,0),""),IFNA(MATCH($B3,'DIVISION 15'!$A$8:$H$8,0),""),IFNA(MATCH($B3,'DIVISION 15'!$A$9:$H$9,0),""),IFNA(MATCH($B3,'DIVISION 15'!$A$10:$H$10,0),""),IFNA(MATCH($B3,'DIVISION 15'!$A$11:$H$11,0),""),IFNA(MATCH($B3,'DIVISION 15'!$A$12:$H$12,0),""),IFNA(MATCH($B3,'DIVISION 15'!$A$13:$H$13,0),""),IFNA(MATCH($B3,'DIVISION 15'!$A$14:$H$14,0),""),IFNA(MATCH($B3,'DIVISION 15'!$A$15:$H$15,0),""),IFNA(MATCH($B3,'DIVISION 15'!$A$16:$H$16,0),""),IFNA(MATCH($B3,'DIVISION 15'!$A$17:$H$17,0),""),IFNA(MATCH($B3,'DIVISION 15'!$A$18:$H$18,0),""))=2,'DIVISION 15'!$B$1,SUM(IFNA(MATCH($B3,'DIVISION 15'!$A$2:$H$2,0),""),IFNA(MATCH($B3,'DIVISION 15'!$A$3:$H$3,0),""),IFNA(MATCH($B3,'DIVISION 15'!$A$4:$H$4,0),""),IFNA(MATCH($B3,'DIVISION 15'!$A$5:$H$5,0),""),IFNA(MATCH($B3,'DIVISION 15'!$A$6:$H$6,0),""),IFNA(MATCH($B3,'DIVISION 15'!$A$7:$H$7,0),""),IFNA(MATCH($B3,'DIVISION 15'!$A$8:$H$8,0),""),IFNA(MATCH($B3,'DIVISION 15'!$A$9:$H$9,0),""),IFNA(MATCH($B3,'DIVISION 15'!$A$10:$H$10,0),""),IFNA(MATCH($B3,'DIVISION 15'!$A$11:$H$11,0),""),IFNA(MATCH($B3,'DIVISION 15'!$A$12:$H$12,0),""),IFNA(MATCH($B3,'DIVISION 15'!$A$13:$H$13,0),""),IFNA(MATCH($B3,'DIVISION 15'!$A$14:$H$14,0),""),IFNA(MATCH($B3,'DIVISION 15'!$A$15:$H$15,0),""),IFNA(MATCH($B3,'DIVISION 15'!$A$16:$H$16,0),""),IFNA(MATCH($B3,'DIVISION 15'!$A$17:$H$17,0),""),IFNA(MATCH($B3,'DIVISION 15'!$A$18:$H$18,0),""))=3,'DIVISION 15'!$C$1,SUM(IFNA(MATCH($B3,'DIVISION 15'!$A$2:$H$2,0),""),IFNA(MATCH($B3,'DIVISION 15'!$A$3:$H$3,0),""),IFNA(MATCH($B3,'DIVISION 15'!$A$4:$H$4,0),""),IFNA(MATCH($B3,'DIVISION 15'!$A$5:$H$5,0),""),IFNA(MATCH($B3,'DIVISION 15'!$A$6:$H$6,0),""),IFNA(MATCH($B3,'DIVISION 15'!$A$7:$H$7,0),""),IFNA(MATCH($B3,'DIVISION 15'!$A$8:$H$8,0),""),IFNA(MATCH($B3,'DIVISION 15'!$A$9:$H$9,0),""),IFNA(MATCH($B3,'DIVISION 15'!$A$10:$H$10,0),""),IFNA(MATCH($B3,'DIVISION 15'!$A$11:$H$11,0),""),IFNA(MATCH($B3,'DIVISION 15'!$A$12:$H$12,0),""),IFNA(MATCH($B3,'DIVISION 15'!$A$13:$H$13,0),""),IFNA(MATCH($B3,'DIVISION 15'!$A$14:$H$14,0),""),IFNA(MATCH($B3,'DIVISION 15'!$A$15:$H$15,0),""),IFNA(MATCH($B3,'DIVISION 15'!$A$16:$H$16,0),""),IFNA(MATCH($B3,'DIVISION 15'!$A$17:$H$17,0),""),IFNA(MATCH($B3,'DIVISION 15'!$A$18:$H$18,0),""))=4,'DIVISION 15'!$D$1,SUM(IFNA(MATCH($B3,'DIVISION 15'!$A$2:$H$2,0),""),IFNA(MATCH($B3,'DIVISION 15'!$A$3:$H$3,0),""),IFNA(MATCH($B3,'DIVISION 15'!$A$4:$H$4,0),""),IFNA(MATCH($B3,'DIVISION 15'!$A$5:$H$5,0),""),IFNA(MATCH($B3,'DIVISION 15'!$A$6:$H$6,0),""),IFNA(MATCH($B3,'DIVISION 15'!$A$7:$H$7,0),""),IFNA(MATCH($B3,'DIVISION 15'!$A$8:$H$8,0),""),IFNA(MATCH($B3,'DIVISION 15'!$A$9:$H$9,0),""),IFNA(MATCH($B3,'DIVISION 15'!$A$10:$H$10,0),""),IFNA(MATCH($B3,'DIVISION 15'!$A$11:$H$11,0),""),IFNA(MATCH($B3,'DIVISION 15'!$A$12:$H$12,0),""),IFNA(MATCH($B3,'DIVISION 15'!$A$13:$H$13,0),""),IFNA(MATCH($B3,'DIVISION 15'!$A$14:$H$14,0),""),IFNA(MATCH($B3,'DIVISION 15'!$A$15:$H$15,0),""),IFNA(MATCH($B3,'DIVISION 15'!$A$16:$H$16,0),""),IFNA(MATCH($B3,'DIVISION 15'!$A$17:$H$17,0),""),IFNA(MATCH($B3,'DIVISION 15'!$A$18:$H$18,0),""))=5,'DIVISION 15'!$E$1,SUM(IFNA(MATCH($B3,'DIVISION 15'!$A$2:$H$2,0),""),IFNA(MATCH($B3,'DIVISION 15'!$A$3:$H$3,0),""),IFNA(MATCH($B3,'DIVISION 15'!$A$4:$H$4,0),""),IFNA(MATCH($B3,'DIVISION 15'!$A$5:$H$5,0),""),IFNA(MATCH($B3,'DIVISION 15'!$A$6:$H$6,0),""),IFNA(MATCH($B3,'DIVISION 15'!$A$7:$H$7,0),""),IFNA(MATCH($B3,'DIVISION 15'!$A$8:$H$8,0),""),IFNA(MATCH($B3,'DIVISION 15'!$A$9:$H$9,0),""),IFNA(MATCH($B3,'DIVISION 15'!$A$10:$H$10,0),""),IFNA(MATCH($B3,'DIVISION 15'!$A$11:$H$11,0),""),IFNA(MATCH($B3,'DIVISION 15'!$A$12:$H$12,0),""),IFNA(MATCH($B3,'DIVISION 15'!$A$13:$H$13,0),""),IFNA(MATCH($B3,'DIVISION 15'!$A$14:$H$14,0),""),IFNA(MATCH($B3,'DIVISION 15'!$A$15:$H$15,0),""),IFNA(MATCH($B3,'DIVISION 15'!$A$16:$H$16,0),""),IFNA(MATCH($B3,'DIVISION 15'!$A$17:$H$17,0),""),IFNA(MATCH($B3,'DIVISION 15'!$A$18:$H$18,0),""))=6,'DIVISION 15'!$F$1,SUM(IFNA(MATCH($B3,'DIVISION 15'!$A$2:$H$2,0),""),IFNA(MATCH($B3,'DIVISION 15'!$A$3:$H$3,0),""),IFNA(MATCH($B3,'DIVISION 15'!$A$4:$H$4,0),""),IFNA(MATCH($B3,'DIVISION 15'!$A$5:$H$5,0),""),IFNA(MATCH($B3,'DIVISION 15'!$A$6:$H$6,0),""),IFNA(MATCH($B3,'DIVISION 15'!$A$7:$H$7,0),""),IFNA(MATCH($B3,'DIVISION 15'!$A$8:$H$8,0),""),IFNA(MATCH($B3,'DIVISION 15'!$A$9:$H$9,0),""),IFNA(MATCH($B3,'DIVISION 15'!$A$10:$H$10,0),""),IFNA(MATCH($B3,'DIVISION 15'!$A$11:$H$11,0),""),IFNA(MATCH($B3,'DIVISION 15'!$A$12:$H$12,0),""),IFNA(MATCH($B3,'DIVISION 15'!$A$13:$H$13,0),""),IFNA(MATCH($B3,'DIVISION 15'!$A$14:$H$14,0),""),IFNA(MATCH($B3,'DIVISION 15'!$A$15:$H$15,0),""),IFNA(MATCH($B3,'DIVISION 15'!$A$16:$H$16,0),""),IFNA(MATCH($B3,'DIVISION 15'!$A$17:$H$17,0),""),IFNA(MATCH($B3,'DIVISION 15'!$A$18:$H$18,0),""))=7,'DIVISION 15'!$G$1,SUM(IFNA(MATCH($B3,'DIVISION 15'!$A$2:$H$2,0),""),IFNA(MATCH($B3,'DIVISION 15'!$A$3:$H$3,0),""),IFNA(MATCH($B3,'DIVISION 15'!$A$4:$H$4,0),""),IFNA(MATCH($B3,'DIVISION 15'!$A$5:$H$5,0),""),IFNA(MATCH($B3,'DIVISION 15'!$A$6:$H$6,0),""),IFNA(MATCH($B3,'DIVISION 15'!$A$7:$H$7,0),""),IFNA(MATCH($B3,'DIVISION 15'!$A$8:$H$8,0),""),IFNA(MATCH($B3,'DIVISION 15'!$A$9:$H$9,0),""),IFNA(MATCH($B3,'DIVISION 15'!$A$10:$H$10,0),""),IFNA(MATCH($B3,'DIVISION 15'!$A$11:$H$11,0),""),IFNA(MATCH($B3,'DIVISION 15'!$A$12:$H$12,0),""),IFNA(MATCH($B3,'DIVISION 15'!$A$13:$H$13,0),""),IFNA(MATCH($B3,'DIVISION 15'!$A$14:$H$14,0),""),IFNA(MATCH($B3,'DIVISION 15'!$A$15:$H$15,0),""),IFNA(MATCH($B3,'DIVISION 15'!$A$16:$H$16,0),""),IFNA(MATCH($B3,'DIVISION 15'!$A$17:$H$17,0),""),IFNA(MATCH($B3,'DIVISION 15'!$A$18:$H$18,0),""))=8,'DIVISION 15'!$H$1) -> EITU | U3: =T3&COUNTIF($T$1:T3,T3) -> EITU1 | V3: =SUMIF(AsistenciaViewJetAdmin!$A$3:$A$101,A3,AsistenciaViewJetAdmin!$C$3:$C$101)/(COUNTIF(AsistenciaViewJetAdmin!$D$102:V$102,">0")+COUNTIF(ActividadesEspeciales!$D$102:V$102,">0"))*100 -> 67.553191
A4: 161 | B4: Valentín Cohen | C4: 905507 | D4: 22/06/2010 | E4: 50416933 | F4: chinobostero09@gmail.com | G4: 1164929717 | H4: Andrea Basile | I4: andrea.marina.basile@gmail.com | J4: 1149361831 | K4: Ricardo cohen | L4: riquicohen@gnail.com | M4: 1149376172 | N4: ORT | O4: Si. En modadon | P4: Futbol | Q4: Nedarim | R4: Sin restricciones | S4: NARANJA | T4: =IFS(SUM(IFNA(MATCH($B4,'DIVISION 15'!$A$2:$H$2,0),""),IFNA(MATCH($B4,'DIVISION 15'!$A$3:$H$3,0),""),IFNA(MATCH($B4,'DIVISION 15'!$A$4:$H$4,0),""),IFNA(MATCH($B4,'DIVISION 15'!$A$5:$H$5,0),""),IFNA(MATCH($B4,'DIVISION 15'!$A$6:$H$6,0),""),IFNA(MATCH($B4,'DIVISION 15'!$A$7:$H$7,0),""),IFNA(MATCH($B4,'DIVISION 15'!$A$8:$H$8,0),""),IFNA(MATCH($B4,'DIVISION 15'!$A$9:$H$9,0),""),IFNA(MATCH($B4,'DIVISION 15'!$A$10:$H$10,0),""),IFNA(MATCH($B4,'DIVISION 15'!$A$11:$H$11,0),""),IFNA(MATCH($B4,'DIVISION 15'!$A$12:$H$12,0),""),IFNA(MATCH($B4,'DIVISION 15'!$A$13:$H$13,0),""),IFNA(MATCH($B4,'DIVISION 15'!$A$14:$H$14,0),""),IFNA(MATCH($B4,'DIVISION 15'!$A$15:$H$15,0),""),IFNA(MATCH($B4,'DIVISION 15'!$A$16:$H$16,0),""),IFNA(MATCH($B4,'DIVISION 15'!$A$17:$H$17,0),""),IFNA(MATCH($B4,'DIVISION 15'!$A$18:$H$18,0),""))=1,'DIVISION 15'!$A$1,SUM(IFNA(MATCH($B4,'DIVISION 15'!$A$2:$H$2,0),""),IFNA(MATCH($B4,'DIVISION 15'!$A$3:$H$3,0),""),IFNA(MATCH($B4,'DIVISION 15'!$A$4:$H$4,0),""),IFNA(MATCH($B4,'DIVISION 15'!$A$5:$H$5,0),""),IFNA(MATCH($B4,'DIVISION 15'!$A$6:$H$6,0),""),IFNA(MATCH($B4,'DIVISION 15'!$A$7:$H$7,0),""),IFNA(MATCH($B4,'DIVISION 15'!$A$8:$H$8,0),""),IFNA(MATCH($B4,'DIVISION 15'!$A$9:$H$9,0),""),IFNA(MATCH($B4,'DIVISION 15'!$A$10:$H$10,0),""),IFNA(MATCH($B4,'DIVISION 15'!$A$11:$H$11,0),""),IFNA(MATCH($B4,'DIVISION 15'!$A$12:$H$12,0),""),IFNA(MATCH($B4,'DIVISION 15'!$A$13:$H$13,0),""),IFNA(MATCH($B4,'DIVISION 15'!$A$14:$H$14,0),""),IFNA(MATCH($B4,'DIVISION 15'!$A$15:$H$15,0),""),IFNA(MATCH($B4,'DIVISION 15'!$A$16:$H$16,0),""),IFNA(MATCH($B4,'DIVISION 15'!$A$17:$H$17,0),""),IFNA(MATCH($B4,'DIVISION 15'!$A$18:$H$18,0),""))=2,'DIVISION 15'!$B$1,SUM(IFNA(MATCH($B4,'DIVISION 15'!$A$2:$H$2,0),""),IFNA(MATCH($B4,'DIVISION 15'!$A$3:$H$3,0),""),IFNA(MATCH($B4,'DIVISION 15'!$A$4:$H$4,0),""),IFNA(MATCH($B4,'DIVISION 15'!$A$5:$H$5,0),""),IFNA(MATCH($B4,'DIVISION 15'!$A$6:$H$6,0),""),IFNA(MATCH($B4,'DIVISION 15'!$A$7:$H$7,0),""),IFNA(MATCH($B4,'DIVISION 15'!$A$8:$H$8,0),""),IFNA(MATCH($B4,'DIVISION 15'!$A$9:$H$9,0),""),IFNA(MATCH($B4,'DIVISION 15'!$A$10:$H$10,0),""),IFNA(MATCH($B4,'DIVISION 15'!$A$11:$H$11,0),""),IFNA(MATCH($B4,'DIVISION 15'!$A$12:$H$12,0),""),IFNA(MATCH($B4,'DIVISION 15'!$A$13:$H$13,0),""),IFNA(MATCH($B4,'DIVISION 15'!$A$14:$H$14,0),""),IFNA(MATCH($B4,'DIVISION 15'!$A$15:$H$15,0),""),IFNA(MATCH($B4,'DIVISION 15'!$A$16:$H$16,0),""),IFNA(MATCH($B4,'DIVISION 15'!$A$17:$H$17,0),""),IFNA(MATCH($B4,'DIVISION 15'!$A$18:$H$18,0),""))=3,'DIVISION 15'!$C$1,SUM(IFNA(MATCH($B4,'DIVISION 15'!$A$2:$H$2,0),""),IFNA(MATCH($B4,'DIVISION 15'!$A$3:$H$3,0),""),IFNA(MATCH($B4,'DIVISION 15'!$A$4:$H$4,0),""),IFNA(MATCH($B4,'DIVISION 15'!$A$5:$H$5,0),""),IFNA(MATCH($B4,'DIVISION 15'!$A$6:$H$6,0),""),IFNA(MATCH($B4,'DIVISION 15'!$A$7:$H$7,0),""),IFNA(MATCH($B4,'DIVISION 15'!$A$8:$H$8,0),""),IFNA(MATCH($B4,'DIVISION 15'!$A$9:$H$9,0),""),IFNA(MATCH($B4,'DIVISION 15'!$A$10:$H$10,0),""),IFNA(MATCH($B4,'DIVISION 15'!$A$11:$H$11,0),""),IFNA(MATCH($B4,'DIVISION 15'!$A$12:$H$12,0),""),IFNA(MATCH($B4,'DIVISION 15'!$A$13:$H$13,0),""),IFNA(MATCH($B4,'DIVISION 15'!$A$14:$H$14,0),""),IFNA(MATCH($B4,'DIVISION 15'!$A$15:$H$15,0),""),IFNA(MATCH($B4,'DIVISION 15'!$A$16:$H$16,0),""),IFNA(MATCH($B4,'DIVISION 15'!$A$17:$H$17,0),""),IFNA(MATCH($B4,'DIVISION 15'!$A$18:$H$18,0),""))=4,'DIVISION 15'!$D$1,SUM(IFNA(MATCH($B4,'DIVISION 15'!$A$2:$H$2,0),""),IFNA(MATCH($B4,'DIVISION 15'!$A$3:$H$3,0),""),IFNA(MATCH($B4,'DIVISION 15'!$A$4:$H$4,0),""),IFNA(MATCH($B4,'DIVISION 15'!$A$5:$H$5,0),""),IFNA(MATCH($B4,'DIVISION 15'!$A$6:$H$6,0),""),IFNA(MATCH($B4,'DIVISION 15'!$A$7:$H$7,0),""),IFNA(MATCH($B4,'DIVISION 15'!$A$8:$H$8,0),""),IFNA(MATCH($B4,'DIVISION 15'!$A$9:$H$9,0),""),IFNA(MATCH($B4,'DIVISION 15'!$A$10:$H$10,0),""),IFNA(MATCH($B4,'DIVISION 15'!$A$11:$H$11,0),""),IFNA(MATCH($B4,'DIVISION 15'!$A$12:$H$12,0),""),IFNA(MATCH($B4,'DIVISION 15'!$A$13:$H$13,0),""),IFNA(MATCH($B4,'DIVISION 15'!$A$14:$H$14,0),""),IFNA(MATCH($B4,'DIVISION 15'!$A$15:$H$15,0),""),IFNA(MATCH($B4,'DIVISION 15'!$A$16:$H$16,0),""),IFNA(MATCH($B4,'DIVISION 15'!$A$17:$H$17,0),""),IFNA(MATCH($B4,'DIVISION 15'!$A$18:$H$18,0),""))=5,'DIVISION 15'!$E$1,SUM(IFNA(MATCH($B4,'DIVISION 15'!$A$2:$H$2,0),""),IFNA(MATCH($B4,'DIVISION 15'!$A$3:$H$3,0),""),IFNA(MATCH($B4,'DIVISION 15'!$A$4:$H$4,0),""),IFNA(MATCH($B4,'DIVISION 15'!$A$5:$H$5,0),""),IFNA(MATCH($B4,'DIVISION 15'!$A$6:$H$6,0),""),IFNA(MATCH($B4,'DIVISION 15'!$A$7:$H$7,0),""),IFNA(MATCH($B4,'DIVISION 15'!$A$8:$H$8,0),""),IFNA(MATCH($B4,'DIVISION 15'!$A$9:$H$9,0),""),IFNA(MATCH($B4,'DIVISION 15'!$A$10:$H$10,0),""),IFNA(MATCH($B4,'DIVISION 15'!$A$11:$H$11,0),""),IFNA(MATCH($B4,'DIVISION 15'!$A$12:$H$12,0),""),IFNA(MATCH($B4,'DIVISION 15'!$A$13:$H$13,0),""),IFNA(MATCH($B4,'DIVISION 15'!$A$14:$H$14,0),""),IFNA(MATCH($B4,'DIVISION 15'!$A$15:$H$15,0),""),IFNA(MATCH($B4,'DIVISION 15'!$A$16:$H$16,0),""),IFNA(MATCH($B4,'DIVISION 15'!$A$17:$H$17,0),""),IFNA(MATCH($B4,'DIVISION 15'!$A$18:$H$18,0),""))=6,'DIVISION 15'!$F$1,SUM(IFNA(MATCH($B4,'DIVISION 15'!$A$2:$H$2,0),""),IFNA(MATCH($B4,'DIVISION 15'!$A$3:$H$3,0),""),IFNA(MATCH($B4,'DIVISION 15'!$A$4:$H$4,0),""),IFNA(MATCH($B4,'DIVISION 15'!$A$5:$H$5,0),""),IFNA(MATCH($B4,'DIVISION 15'!$A$6:$H$6,0),""),IFNA(MATCH($B4,'DIVISION 15'!$A$7:$H$7,0),""),IFNA(MATCH($B4,'DIVISION 15'!$A$8:$H$8,0),""),IFNA(MATCH($B4,'DIVISION 15'!$A$9:$H$9,0),""),IFNA(MATCH($B4,'DIVISION 15'!$A$10:$H$10,0),""),IFNA(MATCH($B4,'DIVISION 15'!$A$11:$H$11,0),""),IFNA(MATCH($B4,'DIVISION 15'!$A$12:$H$12,0),""),IFNA(MATCH($B4,'DIVISION 15'!$A$13:$H$13,0),""),IFNA(MATCH($B4,'DIVISION 15'!$A$14:$H$14,0),""),IFNA(MATCH($B4,'DIVISION 15'!$A$15:$H$15,0),""),IFNA(MATCH($B4,'DIVISION 15'!$A$16:$H$16,0),""),IFNA(MATCH($B4,'DIVISION 15'!$A$17:$H$17,0),""),IFNA(MATCH($B4,'DIVISION 15'!$A$18:$H$18,0),""))=7,'DIVISION 15'!$G$1,SUM(IFNA(MATCH($B4,'DIVISION 15'!$A$2:$H$2,0),""),IFNA(MATCH($B4,'DIVISION 15'!$A$3:$H$3,0),""),IFNA(MATCH($B4,'DIVISION 15'!$A$4:$H$4,0),""),IFNA(MATCH($B4,'DIVISION 15'!$A$5:$H$5,0),""),IFNA(MATCH($B4,'DIVISION 15'!$A$6:$H$6,0),""),IFNA(MATCH($B4,'DIVISION 15'!$A$7:$H$7,0),""),IFNA(MATCH($B4,'DIVISION 15'!$A$8:$H$8,0),""),IFNA(MATCH($B4,'DIVISION 15'!$A$9:$H$9,0),""),IFNA(MATCH($B4,'DIVISION 15'!$A$10:$H$10,0),""),IFNA(MATCH($B4,'DIVISION 15'!$A$11:$H$11,0),""),IFNA(MATCH($B4,'DIVISION 15'!$A$12:$H$12,0),""),IFNA(MATCH($B4,'DIVISION 15'!$A$13:$H$13,0),""),IFNA(MATCH($B4,'DIVISION 15'!$A$14:$H$14,0),""),IFNA(MATCH($B4,'DIVISION 15'!$A$15:$H$15,0),""),IFNA(MATCH($B4,'DIVISION 15'!$A$16:$H$16,0),""),IFNA(MATCH($B4,'DIVISION 15'!$A$17:$H$17,0),""),IFNA(MATCH($B4,'DIVISION 15'!$A$18:$H$18,0),""))=8,'DIVISION 15'!$H$1) -> EITU | U4: =T4&COUNTIF($T$1:T4,T4) -> EITU2 | V4: =SUMIF(AsistenciaViewJetAdmin!$A$3:$A$101,A4,AsistenciaViewJetAdmin!$C$3:$C$101)/(COUNTIF(AsistenciaViewJetAdmin!$D$102:V$102,">0")+COUNTIF(ActividadesEspeciales!$D$102:V$102,">0"))*100 -> 42.021277
A5: 137 | B5: Tomas Garbovetsky | C5: 1030601 | D5: 0706/2010 | E5: 50322872 | F5: totogarbo10@gmail.com | G5: 1140512585 | H5: Melisa Fenig | I5: fenignelisa@hotmail.com | J5: 1168302846 | K5: Alan Garbovetsky | L5: alangarbo@gmail.com | M5: 1151615809 | N5: Ort | O5: Si en ananim y letamid | P5: Futbol | Q5: Nedarim | R5: Sin restricciones | S5: NARANJA | T5: =IFS(SUM(IFNA(MATCH($B5,'DIVISION 15'!$A$2:$H$2,0),""),IFNA(MATCH($B5,'DIVISION 15'!$A$3:$H$3,0),""),IFNA(MATCH($B5,'DIVISION 15'!$A$4:$H$4,0),""),IFNA(MATCH($B5,'DIVISION 15'!$A$5:$H$5,0),""),IFNA(MATCH($B5,'DIVISION 15'!$A$6:$H$6,0),""),IFNA(MATCH($B5,'DIVISION 15'!$A$7:$H$7,0),""),IFNA(MATCH($B5,'DIVISION 15'!$A$8:$H$8,0),""),IFNA(MATCH($B5,'DIVISION 15'!$A$9:$H$9,0),""),IFNA(MATCH($B5,'DIVISION 15'!$A$10:$H$10,0),""),IFNA(MATCH($B5,'DIVISION 15'!$A$11:$H$11,0),""),IFNA(MATCH($B5,'DIVISION 15'!$A$12:$H$12,0),""),IFNA(MATCH($B5,'DIVISION 15'!$A$13:$H$13,0),""),IFNA(MATCH($B5,'DIVISION 15'!$A$14:$H$14,0),""),IFNA(MATCH($B5,'DIVISION 15'!$A$15:$H$15,0),""),IFNA(MATCH($B5,'DIVISION 15'!$A$16:$H$16,0),""),IFNA(MATCH($B5,'DIVISION 15'!$A$17:$H$17,0),""),IFNA(MATCH($B5,'DIVISION 15'!$A$18:$H$18,0),""))=1,'DIVISION 15'!$A$1,SUM(IFNA(MATCH($B5,'DIVISION 15'!$A$2:$H$2,0),""),IFNA(MATCH($B5,'DIVISION 15'!$A$3:$H$3,0),""),IFNA(MATCH($B5,'DIVISION 15'!$A$4:$H$4,0),""),IFNA(MATCH($B5,'DIVISION 15'!$A$5:$H$5,0),""),IFNA(MATCH($B5,'DIVISION 15'!$A$6:$H$6,0),""),IFNA(MATCH($B5,'DIVISION 15'!$A$7:$H$7,0),""),IFNA(MATCH($B5,'DIVISION 15'!$A$8:$H$8,0),""),IFNA(MATCH($B5,'DIVISION 15'!$A$9:$H$9,0),""),IFNA(MATCH($B5,'DIVISION 15'!$A$10:$H$10,0),""),IFNA(MATCH($B5,'DIVISION 15'!$A$11:$H$11,0),""),IFNA(MATCH($B5,'DIVISION 15'!$A$12:$H$12,0),""),IFNA(MATCH($B5,'DIVISION 15'!$A$13:$H$13,0),""),IFNA(MATCH($B5,'DIVISION 15'!$A$14:$H$14,0),""),IFNA(MATCH($B5,'DIVISION 15'!$A$15:$H$15,0),""),IFNA(MATCH($B5,'DIVISION 15'!$A$16:$H$16,0),""),IFNA(MATCH($B5,'DIVISION 15'!$A$17:$H$17,0),""),IFNA(MATCH($B5,'DIVISION 15'!$A$18:$H$18,0),""))=2,'DIVISION 15'!$B$1,SUM(IFNA(MATCH($B5,'DIVISION 15'!$A$2:$H$2,0),""),IFNA(MATCH($B5,'DIVISION 15'!$A$3:$H$3,0),""),IFNA(MATCH($B5,'DIVISION 15'!$A$4:$H$4,0),""),IFNA(MATCH($B5,'DIVISION 15'!$A$5:$H$5,0),""),IFNA(MATCH($B5,'DIVISION 15'!$A$6:$H$6,0),""),IFNA(MATCH($B5,'DIVISION 15'!$A$7:$H$7,0),""),IFNA(MATCH($B5,'DIVISION 15'!$A$8:$H$8,0),""),IFNA(MATCH($B5,'DIVISION 15'!$A$9:$H$9,0),""),IFNA(MATCH($B5,'DIVISION 15'!$A$10:$H$10,0),""),IFNA(MATCH($B5,'DIVISION 15'!$A$11:$H$11,0),""),IFNA(MATCH($B5,'DIVISION 15'!$A$12:$H$12,0),""),IFNA(MATCH($B5,'DIVISION 15'!$A$13:$H$13,0),""),IFNA(MATCH($B5,'DIVISION 15'!$A$14:$H$14,0),""),IFNA(MATCH($B5,'DIVISION 15'!$A$15:$H$15,0),""),IFNA(MATCH($B5,'DIVISION 15'!$A$16:$H$16,0),""),IFNA(MATCH($B5,'DIVISION 15'!$A$17:$H$17,0),""),IFNA(MATCH($B5,'DIVISION 15'!$A$18:$H$18,0),""))=3,'DIVISION 15'!$C$1,SUM(IFNA(MATCH($B5,'DIVISION 15'!$A$2:$H$2,0),""),IFNA(MATCH($B5,'DIVISION 15'!$A$3:$H$3,0),""),IFNA(MATCH($B5,'DIVISION 15'!$A$4:$H$4,0),""),IFNA(MATCH($B5,'DIVISION 15'!$A$5:$H$5,0),""),IFNA(MATCH($B5,'DIVISION 15'!$A$6:$H$6,0),""),IFNA(MATCH($B5,'DIVISION 15'!$A$7:$H$7,0),""),IFNA(MATCH($B5,'DIVISION 15'!$A$8:$H$8,0),""),IFNA(MATCH($B5,'DIVISION 15'!$A$9:$H$9,0),""),IFNA(MATCH($B5,'DIVISION 15'!$A$10:$H$10,0),""),IFNA(MATCH($B5,'DIVISION 15'!$A$11:$H$11,0),""),IFNA(MATCH($B5,'DIVISION 15'!$A$12:$H$12,0),""),IFNA(MATCH($B5,'DIVISION 15'!$A$13:$H$13,0),""),IFNA(MATCH($B5,'DIVISION 15'!$A$14:$H$14,0),""),IFNA(MATCH($B5,'DIVISION 15'!$A$15:$H$15,0),""),IFNA(MATCH($B5,'DIVISION 15'!$A$16:$H$16,0),""),IFNA(MATCH($B5,'DIVISION 15'!$A$17:$H$17,0),""),IFNA(MATCH($B5,'DIVISION 15'!$A$18:$H$18,0),""))=4,'DIVISION 15'!$D$1,SUM(IFNA(MATCH($B5,'DIVISION 15'!$A$2:$H$2,0),""),IFNA(MATCH($B5,'DIVISION 15'!$A$3:$H$3,0),""),IFNA(MATCH($B5,'DIVISION 15'!$A$4:$H$4,0),""),IFNA(MATCH($B5,'DIVISION 15'!$A$5:$H$5,0),""),IFNA(MATCH($B5,'DIVISION 15'!$A$6:$H$6,0),""),IFNA(MATCH($B5,'DIVISION 15'!$A$7:$H$7,0),""),IFNA(MATCH($B5,'DIVISION 15'!$A$8:$H$8,0),""),IFNA(MATCH($B5,'DIVISION 15'!$A$9:$H$9,0),""),IFNA(MATCH($B5,'DIVISION 15'!$A$10:$H$10,0),""),IFNA(MATCH($B5,'DIVISION 15'!$A$11:$H$11,0),""),IFNA(MATCH($B5,'DIVISION 15'!$A$12:$H$12,0),""),IFNA(MATCH($B5,'DIVISION 15'!$A$13:$H$13,0),""),IFNA(MATCH($B5,'DIVISION 15'!$A$14:$H$14,0),""),IFNA(MATCH($B5,'DIVISION 15'!$A$15:$H$15,0),""),IFNA(MATCH($B5,'DIVISION 15'!$A$16:$H$16,0),""),IFNA(MATCH($B5,'DIVISION 15'!$A$17:$H$17,0),""),IFNA(MATCH($B5,'DIVISION 15'!$A$18:$H$18,0),""))=5,'DIVISION 15'!$E$1,SUM(IFNA(MATCH($B5,'DIVISION 15'!$A$2:$H$2,0),""),IFNA(MATCH($B5,'DIVISION 15'!$A$3:$H$3,0),""),IFNA(MATCH($B5,'DIVISION 15'!$A$4:$H$4,0),""),IFNA(MATCH($B5,'DIVISION 15'!$A$5:$H$5,0),""),IFNA(MATCH($B5,'DIVISION 15'!$A$6:$H$6,0),""),IFNA(MATCH($B5,'DIVISION 15'!$A$7:$H$7,0),""),IFNA(MATCH($B5,'DIVISION 15'!$A$8:$H$8,0),""),IFNA(MATCH($B5,'DIVISION 15'!$A$9:$H$9,0),""),IFNA(MATCH($B5,'DIVISION 15'!$A$10:$H$10,0),""),IFNA(MATCH($B5,'DIVISION 15'!$A$11:$H$11,0),""),IFNA(MATCH($B5,'DIVISION 15'!$A$12:$H$12,0),""),IFNA(MATCH($B5,'DIVISION 15'!$A$13:$H$13,0),""),IFNA(MATCH($B5,'DIVISION 15'!$A$14:$H$14,0),""),IFNA(MATCH($B5,'DIVISION 15'!$A$15:$H$15,0),""),IFNA(MATCH($B5,'DIVISION 15'!$A$16:$H$16,0),""),IFNA(MATCH($B5,'DIVISION 15'!$A$17:$H$17,0),""),IFNA(MATCH($B5,'DIVISION 15'!$A$18:$H$18,0),""))=6,'DIVISION 15'!$F$1,SUM(IFNA(MATCH($B5,'DIVISION 15'!$A$2:$H$2,0),""),IFNA(MATCH($B5,'DIVISION 15'!$A$3:$H$3,0),""),IFNA(MATCH($B5,'DIVISION 15'!$A$4:$H$4,0),""),IFNA(MATCH($B5,'DIVISION 15'!$A$5:$H$5,0),""),IFNA(MATCH($B5,'DIVISION 15'!$A$6:$H$6,0),""),IFNA(MATCH($B5,'DIVISION 15'!$A$7:$H$7,0),""),IFNA(MATCH($B5,'DIVISION 15'!$A$8:$H$8,0),""),IFNA(MATCH($B5,'DIVISION 15'!$A$9:$H$9,0),""),IFNA(MATCH($B5,'DIVISION 15'!$A$10:$H$10,0),""),IFNA(MATCH($B5,'DIVISION 15'!$A$11:$H$11,0),""),IFNA(MATCH($B5,'DIVISION 15'!$A$12:$H$12,0),""),IFNA(MATCH($B5,'DIVISION 15'!$A$13:$H$13,0),""),IFNA(MATCH($B5,'DIVISION 15'!$A$14:$H$14,0),""),IFNA(MATCH($B5,'DIVISION 15'!$A$15:$H$15,0),""),IFNA(MATCH($B5,'DIVISION 15'!$A$16:$H$16,0),""),IFNA(MATCH($B5,'DIVISION 15'!$A$17:$H$17,0),""),IFNA(MATCH($B5,'DIVISION 15'!$A$18:$H$18,0),""))=7,'DIVISION 15'!$G$1,SUM(IFNA(MATCH($B5,'DIVISION 15'!$A$2:$H$2,0),""),IFNA(MATCH($B5,'DIVISION 15'!$A$3:$H$3,0),""),IFNA(MATCH($B5,'DIVISION 15'!$A$4:$H$4,0),""),IFNA(MATCH($B5,'DIVISION 15'!$A$5:$H$5,0),""),IFNA(MATCH($B5,'DIVISION 15'!$A$6:$H$6,0),""),IFNA(MATCH($B5,'DIVISION 15'!$A$7:$H$7,0),""),IFNA(MATCH($B5,'DIVISION 15'!$A$8:$H$8,0),""),IFNA(MATCH($B5,'DIVISION 15'!$A$9:$H$9,0),""),IFNA(MATCH($B5,'DIVISION 15'!$A$10:$H$10,0),""),IFNA(MATCH($B5,'DIVISION 15'!$A$11:$H$11,0),""),IFNA(MATCH($B5,'DIVISION 15'!$A$12:$H$12,0),""),IFNA(MATCH($B5,'DIVISION 15'!$A$13:$H$13,0),""),IFNA(MATCH($B5,'DIVISION 15'!$A$14:$H$14,0),""),IFNA(MATCH($B5,'DIVISION 15'!$A$15:$H$15,0),""),IFNA(MATCH($B5,'DIVISION 15'!$A$16:$H$16,0),""),IFNA(MATCH($B5,'DIVISION 15'!$A$17:$H$17,0),""),IFNA(MATCH($B5,'DIVISION 15'!$A$18:$H$18,0),""))=8,'DIVISION 15'!$H$1) -> DAIU | U5: =T5&COUNTIF($T$1:T5,T5) -> DAIU1 | V5: =SUMIF(AsistenciaViewJetAdmin!$A$3:$A$101,A5,AsistenciaViewJetAdmin!$C$3:$C$101)/(COUNTIF(AsistenciaViewJetAdmin!$D$102:V$102,">0")+COUNTIF(ActividadesEspeciales!$D$102:V$102,">0"))*100 -> 71.808511
A6: 100 | B6: Tomas Gameroff | C6: 994503 | D6: 17/12/09 | E6: 49960126 | F6: tomigameroff@gmail.com | G6: 1132391205 | H6: Nancy Buschenbaum | I6: nbuschenbaum@gmail.com | J6: 115-626-2121 | K6: Diego Gameroff | L6: gameroffdiego@gmail.com | M6: 114-992-3061 | N6: Ort | O6: Madrij | P6: Futbol Padel | Q6: Jashibut | R6: Sin restricciones | S6: NARANJA | T6: =IFS(SUM(IFNA(MATCH($B6,'DIVISION 15'!$A$2:$H$2,0),""),IFNA(MATCH($B6,'DIVISION 15'!$A$3:$H$3,0),""),IFNA(MATCH($B6,'DIVISION 15'!$A$4:$H$4,0),""),IFNA(MATCH($B6,'DIVISION 15'!$A$5:$H$5,0),""),IFNA(MATCH($B6,'DIVISION 15'!$A$6:$H$6,0),""),IFNA(MATCH($B6,'DIVISION 15'!$A$7:$H$7,0),""),IFNA(MATCH($B6,'DIVISION 15'!$A$8:$H$8,0),""),IFNA(MATCH($B6,'DIVISION 15'!$A$9:$H$9,0),""),IFNA(MATCH($B6,'DIVISION 15'!$A$10:$H$10,0),""),IFNA(MATCH($B6,'DIVISION 15'!$A$11:$H$11,0),""),IFNA(MATCH($B6,'DIVISION 15'!$A$12:$H$12,0),""),IFNA(MATCH($B6,'DIVISION 15'!$A$13:$H$13,0),""),IFNA(MATCH($B6,'DIVISION 15'!$A$14:$H$14,0),""),IFNA(MATCH($B6,'DIVISION 15'!$A$15:$H$15,0),""),IFNA(MATCH($B6,'DIVISION 15'!$A$16:$H$16,0),""),IFNA(MATCH($B6,'DIVISION 15'!$A$17:$H$17,0),""),IFNA(MATCH($B6,'DIVISION 15'!$A$18:$H$18,0),""))=1,'DIVISION 15'!$A$1,SUM(IFNA(MATCH($B6,'DIVISION 15'!$A$2:$H$2,0),""),IFNA(MATCH($B6,'DIVISION 15'!$A$3:$H$3,0),""),IFNA(MATCH($B6,'DIVISION 15'!$A$4:$H$4,0),""),IFNA(MATCH($B6,'DIVISION 15'!$A$5:$H$5,0),""),IFNA(MATCH($B6,'DIVISION 15'!$A$6:$H$6,0),""),IFNA(MATCH($B6,'DIVISION 15'!$A$7:$H$7,0),""),IFNA(MATCH($B6,'DIVISION 15'!$A$8:$H$8,0),""),IFNA(MATCH($B6,'DIVISION 15'!$A$9:$H$9,0),""),IFNA(MATCH($B6,'DIVISION 15'!$A$10:$H$10,0),""),IFNA(MATCH($B6,'DIVISION 15'!$A$11:$H$11,0),""),IFNA(MATCH($B6,'DIVISION 15'!$A$12:$H$12,0),""),IFNA(MATCH($B6,'DIVISION 15'!$A$13:$H$13,0),""),IFNA(MATCH($B6,'DIVISION 15'!$A$14:$H$14,0),""),IFNA(MATCH($B6,'DIVISION 15'!$A$15:$H$15,0),""),IFNA(MATCH($B6,'DIVISION 15'!$A$16:$H$16,0),""),IFNA(MATCH($B6,'DIVISION 15'!$A$17:$H$17,0),""),IFNA(MATCH($B6,'DIVISION 15'!$A$18:$H$18,0),""))=2,'DIVISION 15'!$B$1,SUM(IFNA(MATCH($B6,'DIVISION 15'!$A$2:$H$2,0),""),IFNA(MATCH($B6,'DIVISION 15'!$A$3:$H$3,0),""),IFNA(MATCH($B6,'DIVISION 15'!$A$4:$H$4,0),""),IFNA(MATCH($B6,'DIVISION 15'!$A$5:$H$5,0),""),IFNA(MATCH($B6,'DIVISION 15'!$A$6:$H$6,0),""),IFNA(MATCH($B6,'DIVISION 15'!$A$7:$H$7,0),""),IFNA(MATCH($B6,'DIVISION 15'!$A$8:$H$8,0),""),IFNA(MATCH($B6,'DIVISION 15'!$A$9:$H$9,0),""),IFNA(MATCH($B6,'DIVISION 15'!$A$10:$H$10,0),""),IFNA(MATCH($B6,'DIVISION 15'!$A$11:$H$11,0),""),IFNA(MATCH($B6,'DIVISION 15'!$A$12:$H$12,0),""),IFNA(MATCH($B6,'DIVISION 15'!$A$13:$H$13,0),""),IFNA(MATCH($B6,'DIVISION 15'!$A$14:$H$14,0),""),IFNA(MATCH($B6,'DIVISION 15'!$A$15:$H$15,0),""),IFNA(MATCH($B6,'DIVISION 15'!$A$16:$H$16,0),""),IFNA(MATCH($B6,'DIVISION 15'!$A$17:$H$17,0),""),IFNA(MATCH($B6,'DIVISION 15'!$A$18:$H$18,0),""))=3,'DIVISION 15'!$C$1,SUM(IFNA(MATCH($B6,'DIVISION 15'!$A$2:$H$2,0),""),IFNA(MATCH($B6,'DIVISION 15'!$A$3:$H$3,0),""),IFNA(MATCH($B6,'DIVISION 15'!$A$4:$H$4,0),""),IFNA(MATCH($B6,'DIVISION 15'!$A$5:$H$5,0),""),IFNA(MATCH($B6,'DIVISION 15'!$A$6:$H$6,0),""),IFNA(MATCH($B6,'DIVISION 15'!$A$7:$H$7,0),""),IFNA(MATCH($B6,'DIVISION 15'!$A$8:$H$8,0),""),IFNA(MATCH($B6,'DIVISION 15'!$A$9:$H$9,0),""),IFNA(MATCH($B6,'DIVISION 15'!$A$10:$H$10,0),""),IFNA(MATCH($B6,'DIVISION 15'!$A$11:$H$11,0),""),IFNA(MATCH($B6,'DIVISION 15'!$A$12:$H$12,0),""),IFNA(MATCH($B6,'DIVISION 15'!$A$13:$H$13,0),""),IFNA(MATCH($B6,'DIVISION 15'!$A$14:$H$14,0),""),IFNA(MATCH($B6,'DIVISION 15'!$A$15:$H$15,0),""),IFNA(MATCH($B6,'DIVISION 15'!$A$16:$H$16,0),""),IFNA(MATCH($B6,'DIVISION 15'!$A$17:$H$17,0),""),IFNA(MATCH($B6,'DIVISION 15'!$A$18:$H$18,0),""))=4,'DIVISION 15'!$D$1,SUM(IFNA(MATCH($B6,'DIVISION 15'!$A$2:$H$2,0),""),IFNA(MATCH($B6,'DIVISION 15'!$A$3:$H$3,0),""),IFNA(MATCH($B6,'DIVISION 15'!$A$4:$H$4,0),""),IFNA(MATCH($B6,'DIVISION 15'!$A$5:$H$5,0),""),IFNA(MATCH($B6,'DIVISION 15'!$A$6:$H$6,0),""),IFNA(MATCH($B6,'DIVISION 15'!$A$7:$H$7,0),""),IFNA(MATCH($B6,'DIVISION 15'!$A$8:$H$8,0),""),IFNA(MATCH($B6,'DIVISION 15'!$A$9:$H$9,0),""),IFNA(MATCH($B6,'DIVISION 15'!$A$10:$H$10,0),""),IFNA(MATCH($B6,'DIVISION 15'!$A$11:$H$11,0),""),IFNA(MATCH($B6,'DIVISION 15'!$A$12:$H$12,0),""),IFNA(MATCH($B6,'DIVISION 15'!$A$13:$H$13,0),""),IFNA(MATCH($B6,'DIVISION 15'!$A$14:$H$14,0),""),IFNA(MATCH($B6,'DIVISION 15'!$A$15:$H$15,0),""),IFNA(MATCH($B6,'DIVISION 15'!$A$16:$H$16,0),""),IFNA(MATCH($B6,'DIVISION 15'!$A$17:$H$17,0),""),IFNA(MATCH($B6,'DIVISION 15'!$A$18:$H$18,0),""))=5,'DIVISION 15'!$E$1,SUM(IFNA(MATCH($B6,'DIVISION 15'!$A$2:$H$2,0),""),IFNA(MATCH($B6,'DIVISION 15'!$A$3:$H$3,0),""),IFNA(MATCH($B6,'DIVISION 15'!$A$4:$H$4,0),""),IFNA(MATCH($B6,'DIVISION 15'!$A$5:$H$5,0),""),IFNA(MATCH($B6,'DIVISION 15'!$A$6:$H$6,0),""),IFNA(MATCH($B6,'DIVISION 15'!$A$7:$H$7,0),""),IFNA(MATCH($B6,'DIVISION 15'!$A$8:$H$8,0),""),IFNA(MATCH($B6,'DIVISION 15'!$A$9:$H$9,0),""),IFNA(MATCH($B6,'DIVISION 15'!$A$10:$H$10,0),""),IFNA(MATCH($B6,'DIVISION 15'!$A$11:$H$11,0),""),IFNA(MATCH($B6,'DIVISION 15'!$A$12:$H$12,0),""),IFNA(MATCH($B6,'DIVISION 15'!$A$13:$H$13,0),""),IFNA(MATCH($B6,'DIVISION 15'!$A$14:$H$14,0),""),IFNA(MATCH($B6,'DIVISION 15'!$A$15:$H$15,0),""),IFNA(MATCH($B6,'DIVISION 15'!$A$16:$H$16,0),""),IFNA(MATCH($B6,'DIVISION 15'!$A$17:$H$17,0),""),IFNA(MATCH($B6,'DIVISION 15'!$A$18:$H$18,0),""))=6,'DIVISION 15'!$F$1,SUM(IFNA(MATCH($B6,'DIVISION 15'!$A$2:$H$2,0),""),IFNA(MATCH($B6,'DIVISION 15'!$A$3:$H$3,0),""),IFNA(MATCH($B6,'DIVISION 15'!$A$4:$H$4,0),""),IFNA(MATCH($B6,'DIVISION 15'!$A$5:$H$5,0),""),IFNA(MATCH($B6,'DIVISION 15'!$A$6:$H$6,0),""),IFNA(MATCH($B6,'DIVISION 15'!$A$7:$H$7,0),""),IFNA(MATCH($B6,'DIVISION 15'!$A$8:$H$8,0),""),IFNA(MATCH($B6,'DIVISION 15'!$A$9:$H$9,0),""),IFNA(MATCH($B6,'DIVISION 15'!$A$10:$H$10,0),""),IFNA(MATCH($B6,'DIVISION 15'!$A$11:$H$11,0),""),IFNA(MATCH($B6,'DIVISION 15'!$A$12:$H$12,0),""),IFNA(MATCH($B6,'DIVISION 15'!$A$13:$H$13,0),""),IFNA(MATCH($B6,'DIVISION 15'!$A$14:$H$14,0),""),IFNA(MATCH($B6,'DIVISION 15'!$A$15:$H$15,0),""),IFNA(MATCH($B6,'DIVISION 15'!$A$16:$H$16,0),""),IFNA(MATCH($B6,'DIVISION 15'!$A$17:$H$17,0),""),IFNA(MATCH($B6,'DIVISION 15'!$A$18:$H$18,0),""))=7,'DIVISION 15'!$G$1,SUM(IFNA(MATCH($B6,'DIVISION 15'!$A$2:$H$2,0),""),IFNA(MATCH($B6,'DIVISION 15'!$A$3:$H$3,0),""),IFNA(MATCH($B6,'DIVISION 15'!$A$4:$H$4,0),""),IFNA(MATCH($B6,'DIVISION 15'!$A$5:$H$5,0),""),IFNA(MATCH($B6,'DIVISION 15'!$A$6:$H$6,0),""),IFNA(MATCH($B6,'DIVISION 15'!$A$7:$H$7,0),""),IFNA(MATCH($B6,'DIVISION 15'!$A$8:$H$8,0),""),IFNA(MATCH($B6,'DIVISION 15'!$A$9:$H$9,0),""),IFNA(MATCH($B6,'DIVISION 15'!$A$10:$H$10,0),""),IFNA(MATCH($B6,'DIVISION 15'!$A$11:$H$11,0),""),IFNA(MATCH($B6,'DIVISION 15'!$A$12:$H$12,0),""),IFNA(MATCH($B6,'DIVISION 15'!$A$13:$H$13,0),""),IFNA(MATCH($B6,'DIVISION 15'!$A$14:$H$14,0),""),IFNA(MATCH($B6,'DIVISION 15'!$A$15:$H$15,0),""),IFNA(MATCH($B6,'DIVISION 15'!$A$16:$H$16,0),""),IFNA(MATCH($B6,'DIVISION 15'!$A$17:$H$17,0),""),IFNA(MATCH($B6,'DIVISION 15'!$A$18:$H$18,0),""))=8,'DIVISION 15'!$H$1) -> GONZI | U6: =T6&COUNTIF($T$1:T6,T6) -> GONZI1 | V6: =SUMIF(AsistenciaViewJetAdmin!$A$3:$A$101,A6,AsistenciaViewJetAdmin!$C$3:$C$101)/(COUNTIF(AsistenciaViewJetAdmin!$D$102:V$102,">0")+COUNTIF(ActividadesEspeciales!$D$102:V$102,">0"))*100 -> 66.489362
A7: 127 | B7: Tomas Alma | C7: 1083800 | D7: 29/01/2010 | E7: 49982841 | F7: tomasmarcosalma@gmail.com | G7: 68727061 | H7: Karen nakache | I7: turkita@gmail.com | J7: 11 6280-5331 | K7: Mariano alma | L7: marianoalma@hotmail.com | M7: +54 9 11 5762-2480 | N7: Wolfsohn | O7: Mondon sofi alma | P7: Tenis | Q7: Nedarim | R7: Kosher | S7: AZUL | T7: =IFS(SUM(IFNA(MATCH($B7,'DIVISION 15'!$A$2:$H$2,0),""),IFNA(MATCH($B7,'DIVISION 15'!$A$3:$H$3,0),""),IFNA(MATCH($B7,'DIVISION 15'!$A$4:$H$4,0),""),IFNA(MATCH($B7,'DIVISION 15'!$A$5:$H$5,0),""),IFNA(MATCH($B7,'DIVISION 15'!$A$6:$H$6,0),""),IFNA(MATCH($B7,'DIVISION 15'!$A$7:$H$7,0),""),IFNA(MATCH($B7,'DIVISION 15'!$A$8:$H$8,0),""),IFNA(MATCH($B7,'DIVISION 15'!$A$9:$H$9,0),""),IFNA(MATCH($B7,'DIVISION 15'!$A$10:$H$10,0),""),IFNA(MATCH($B7,'DIVISION 15'!$A$11:$H$11,0),""),IFNA(MATCH($B7,'DIVISION 15'!$A$12:$H$12,0),""),IFNA(MATCH($B7,'DIVISION 15'!$A$13:$H$13,0),""),IFNA(MATCH($B7,'DIVISION 15'!$A$14:$H$14,0),""),IFNA(MATCH($B7,'DIVISION 15'!$A$15:$H$15,0),""),IFNA(MATCH($B7,'DIVISION 15'!$A$16:$H$16,0),""),IFNA(MATCH($B7,'DIVISION 15'!$A$17:$H$17,0),""),IFNA(MATCH($B7,'DIVISION 15'!$A$18:$H$18,0),""))=1,'DIVISION 15'!$A$1,SUM(IFNA(MATCH($B7,'DIVISION 15'!$A$2:$H$2,0),""),IFNA(MATCH($B7,'DIVISION 15'!$A$3:$H$3,0),""),IFNA(MATCH($B7,'DIVISION 15'!$A$4:$H$4,0),""),IFNA(MATCH($B7,'DIVISION 15'!$A$5:$H$5,0),""),IFNA(MATCH($B7,'DIVISION 15'!$A$6:$H$6,0),""),IFNA(MATCH($B7,'DIVISION 15'!$A$7:$H$7,0),""),IFNA(MATCH($B7,'DIVISION 15'!$A$8:$H$8,0),""),IFNA(MATCH($B7,'DIVISION 15'!$A$9:$H$9,0),""),IFNA(MATCH($B7,'DIVISION 15'!$A$10:$H$10,0),""),IFNA(MATCH($B7,'DIVISION 15'!$A$11:$H$11,0),""),IFNA(MATCH($B7,'DIVISION 15'!$A$12:$H$12,0),""),IFNA(MATCH($B7,'DIVISION 15'!$A$13:$H$13,0),""),IFNA(MATCH($B7,'DIVISION 15'!$A$14:$H$14,0),""),IFNA(MATCH($B7,'DIVISION 15'!$A$15:$H$15,0),""),IFNA(MATCH($B7,'DIVISION 15'!$A$16:$H$16,0),""),IFNA(MATCH($B7,'DIVISION 15'!$A$17:$H$17,0),""),IFNA(MATCH($B7,'DIVISION 15'!$A$18:$H$18,0),""))=2,'DIVISION 15'!$B$1,SUM(IFNA(MATCH($B7,'DIVISION 15'!$A$2:$H$2,0),""),IFNA(MATCH($B7,'DIVISION 15'!$A$3:$H$3,0),""),IFNA(MATCH($B7,'DIVISION 15'!$A$4:$H$4,0),""),IFNA(MATCH($B7,'DIVISION 15'!$A$5:$H$5,0),""),IFNA(MATCH($B7,'DIVISION 15'!$A$6:$H$6,0),""),IFNA(MATCH($B7,'DIVISION 15'!$A$7:$H$7,0),""),IFNA(MATCH($B7,'DIVISION 15'!$A$8:$H$8,0),""),IFNA(MATCH($B7,'DIVISION 15'!$A$9:$H$9,0),""),IFNA(MATCH($B7,'DIVISION 15'!$A$10:$H$10,0),""),IFNA(MATCH($B7,'DIVISION 15'!$A$11:$H$11,0),""),IFNA(MATCH($B7,'DIVISION 15'!$A$12:$H$12,0),""),IFNA(MATCH($B7,'DIVISION 15'!$A$13:$H$13,0),""),IFNA(MATCH($B7,'DIVISION 15'!$A$14:$H$14,0),""),IFNA(MATCH($B7,'DIVISION 15'!$A$15:$H$15,0),""),IFNA(MATCH($B7,'DIVISION 15'!$A$16:$H$16,0),""),IFNA(MATCH($B7,'DIVISION 15'!$A$17:$H$17,0),""),IFNA(MATCH($B7,'DIVISION 15'!$A$18:$H$18,0),""))=3,'DIVISION 15'!$C$1,SUM(IFNA(MATCH($B7,'DIVISION 15'!$A$2:$H$2,0),""),IFNA(MATCH($B7,'DIVISION 15'!$A$3:$H$3,0),""),IFNA(MATCH($B7,'DIVISION 15'!$A$4:$H$4,0),""),IFNA(MATCH($B7,'DIVISION 15'!$A$5:$H$5,0),""),IFNA(MATCH($B7,'DIVISION 15'!$A$6:$H$6,0),""),IFNA(MATCH($B7,'DIVISION 15'!$A$7:$H$7,0),""),IFNA(MATCH($B7,'DIVISION 15'!$A$8:$H$8,0),""),IFNA(MATCH($B7,'DIVISION 15'!$A$9:$H$9,0),""),IFNA(MATCH($B7,'DIVISION 15'!$A$10:$H$10,0),""),IFNA(MATCH($B7,'DIVISION 15'!$A$11:$H$11,0),""),IFNA(MATCH($B7,'DIVISION 15'!$A$12:$H$12,0),""),IFNA(MATCH($B7,'DIVISION 15'!$A$13:$H$13,0),""),IFNA(MATCH($B7,'DIVISION 15'!$A$14:$H$14,0),""),IFNA(MATCH($B7,'DIVISION 15'!$A$15:$H$15,0),""),IFNA(MATCH($B7,'DIVISION 15'!$A$16:$H$16,0),""),IFNA(MATCH($B7,'DIVISION 15'!$A$17:$H$17,0),""),IFNA(MATCH($B7,'DIVISION 15'!$A$18:$H$18,0),""))=4,'DIVISION 15'!$D$1,SUM(IFNA(MATCH($B7,'DIVISION 15'!$A$2:$H$2,0),""),IFNA(MATCH($B7,'DIVISION 15'!$A$3:$H$3,0),""),IFNA(MATCH($B7,'DIVISION 15'!$A$4:$H$4,0),""),IFNA(MATCH($B7,'DIVISION 15'!$A$5:$H$5,0),""),IFNA(MATCH($B7,'DIVISION 15'!$A$6:$H$6,0),""),IFNA(MATCH($B7,'DIVISION 15'!$A$7:$H$7,0),""),IFNA(MATCH($B7,'DIVISION 15'!$A$8:$H$8,0),""),IFNA(MATCH($B7,'DIVISION 15'!$A$9:$H$9,0),""),IFNA(MATCH($B7,'DIVISION 15'!$A$10:$H$10,0),""),IFNA(MATCH($B7,'DIVISION 15'!$A$11:$H$11,0),""),IFNA(MATCH($B7,'DIVISION 15'!$A$12:$H$12,0),""),IFNA(MATCH($B7,'DIVISION 15'!$A$13:$H$13,0),""),IFNA(MATCH($B7,'DIVISION 15'!$A$14:$H$14,0),""),IFNA(MATCH($B7,'DIVISION 15'!$A$15:$H$15,0),""),IFNA(MATCH($B7,'DIVISION 15'!$A$16:$H$16,0),""),IFNA(MATCH($B7,'DIVISION 15'!$A$17:$H$17,0),""),IFNA(MATCH($B7,'DIVISION 15'!$A$18:$H$18,0),""))=5,'DIVISION 15'!$E$1,SUM(IFNA(MATCH($B7,'DIVISION 15'!$A$2:$H$2,0),""),IFNA(MATCH($B7,'DIVISION 15'!$A$3:$H$3,0),""),IFNA(MATCH($B7,'DIVISION 15'!$A$4:$H$4,0),""),IFNA(MATCH($B7,'DIVISION 15'!$A$5:$H$5,0),""),IFNA(MATCH($B7,'DIVISION 15'!$A$6:$H$6,0),""),IFNA(MATCH($B7,'DIVISION 15'!$A$7:$H$7,0),""),IFNA(MATCH($B7,'DIVISION 15'!$A$8:$H$8,0),""),IFNA(MATCH($B7,'DIVISION 15'!$A$9:$H$9,0),""),IFNA(MATCH($B7,'DIVISION 15'!$A$10:$H$10,0),""),IFNA(MATCH($B7,'DIVISION 15'!$A$11:$H$11,0),""),IFNA(MATCH($B7,'DIVISION 15'!$A$12:$H$12,0),""),IFNA(MATCH($B7,'DIVISION 15'!$A$13:$H$13,0),""),IFNA(MATCH($B7,'DIVISION 15'!$A$14:$H$14,0),""),IFNA(MATCH($B7,'DIVISION 15'!$A$15:$H$15,0),""),IFNA(MATCH($B7,'DIVISION 15'!$A$16:$H$16,0),""),IFNA(MATCH($B7,'DIVISION 15'!$A$17:$H$17,0),""),IFNA(MATCH($B7,'DIVISION 15'!$A$18:$H$18,0),""))=6,'DIVISION 15'!$F$1,SUM(IFNA(MATCH($B7,'DIVISION 15'!$A$2:$H$2,0),""),IFNA(MATCH($B7,'DIVISION 15'!$A$3:$H$3,0),""),IFNA(MATCH($B7,'DIVISION 15'!$A$4:$H$4,0),""),IFNA(MATCH($B7,'DIVISION 15'!$A$5:$H$5,0),""),IFNA(MATCH($B7,'DIVISION 15'!$A$6:$H$6,0),""),IFNA(MATCH($B7,'DIVISION 15'!$A$7:$H$7,0),""),IFNA(MATCH($B7,'DIVISION 15'!$A$8:$H$8,0),""),IFNA(MATCH($B7,'DIVISION 15'!$A$9:$H$9,0),""),IFNA(MATCH($B7,'DIVISION 15'!$A$10:$H$10,0),""),IFNA(MATCH($B7,'DIVISION 15'!$A$11:$H$11,0),""),IFNA(MATCH($B7,'DIVISION 15'!$A$12:$H$12,0),""),IFNA(MATCH($B7,'DIVISION 15'!$A$13:$H$13,0),""),IFNA(MATCH($B7,'DIVISION 15'!$A$14:$H$14,0),""),IFNA(MATCH($B7,'DIVISION 15'!$A$15:$H$15,0),""),IFNA(MATCH($B7,'DIVISION 15'!$A$16:$H$16,0),""),IFNA(MATCH($B7,'DIVISION 15'!$A$17:$H$17,0),""),IFNA(MATCH($B7,'DIVISION 15'!$A$18:$H$18,0),""))=7,'DIVISION 15'!$G$1,SUM(IFNA(MATCH($B7,'DIVISION 15'!$A$2:$H$2,0),""),IFNA(MATCH($B7,'DIVISION 15'!$A$3:$H$3,0),""),IFNA(MATCH($B7,'DIVISION 15'!$A$4:$H$4,0),""),IFNA(MATCH($B7,'DIVISION 15'!$A$5:$H$5,0),""),IFNA(MATCH($B7,'DIVISION 15'!$A$6:$H$6,0),""),IFNA(MATCH($B7,'DIVISION 15'!$A$7:$H$7,0),""),IFNA(MATCH($B7,'DIVISION 15'!$A$8:$H$8,0),""),IFNA(MATCH($B7,'DIVISION 15'!$A$9:$H$9,0),""),IFNA(MATCH($B7,'DIVISION 15'!$A$10:$H$10,0),""),IFNA(MATCH($B7,'DIVISION 15'!$A$11:$H$11,0),""),IFNA(MATCH($B7,'DIVISION 15'!$A$12:$H$12,0),""),IFNA(MATCH($B7,'DIVISION 15'!$A$13:$H$13,0),""),IFNA(MATCH($B7,'DIVISION 15'!$A$14:$H$14,0),""),IFNA(MATCH($B7,'DIVISION 15'!$A$15:$H$15,0),""),IFNA(MATCH($B7,'DIVISION 15'!$A$16:$H$16,0),""),IFNA(MATCH($B7,'DIVISION 15'!$A$17:$H$17,0),""),IFNA(MATCH($B7,'DIVISION 15'!$A$18:$H$18,0),""))=8,'DIVISION 15'!$H$1) -> MARTO | U7: =T7&COUNTIF($T$1:T7,T7) -> MARTO1 | V7: =SUMIF(AsistenciaViewJetAdmin!$A$3:$A$101,A7,AsistenciaViewJetAdmin!$C$3:$C$101)/(COUNTIF(AsistenciaViewJetAdmin!$D$102:V$102,">0")+COUNTIF(ActividadesEspeciales!$D$102:V$102,">0"))*100 -> 46.276596
A8: 218 | B8: Tobias Losicer | C8: 1098402 | D8: 40097 | E8: 49905586 | F8: tobiaslosicer@gmail.com | G8: 1125465099 | H8: Javier Losicer | I8: jlosicer@gmail.com | J8: 1157426573 | K8: Constanza Saul | L8: conisaul@gmail.com | M8: 1151758035 | N8: ORT ALMAGRO | O8: Bogrim Mayor | P8: no | Q8: Nedarim | R8: Sin restricciones | S8: AZUL | T8: =IFS(SUM(IFNA(MATCH($B8,'DIVISION 15'!$A$2:$H$2,0),""),IFNA(MATCH($B8,'DIVISION 15'!$A$3:$H$3,0),""),IFNA(MATCH($B8,'DIVISION 15'!$A$4:$H$4,0),""),IFNA(MATCH($B8,'DIVISION 15'!$A$5:$H$5,0),""),IFNA(MATCH($B8,'DIVISION 15'!$A$6:$H$6,0),""),IFNA(MATCH($B8,'DIVISION 15'!$A$7:$H$7,0),""),IFNA(MATCH($B8,'DIVISION 15'!$A$8:$H$8,0),""),IFNA(MATCH($B8,'DIVISION 15'!$A$9:$H$9,0),""),IFNA(MATCH($B8,'DIVISION 15'!$A$10:$H$10,0),""),IFNA(MATCH($B8,'DIVISION 15'!$A$11:$H$11,0),""),IFNA(MATCH($B8,'DIVISION 15'!$A$12:$H$12,0),""),IFNA(MATCH($B8,'DIVISION 15'!$A$13:$H$13,0),""),IFNA(MATCH($B8,'DIVISION 15'!$A$14:$H$14,0),""),IFNA(MATCH($B8,'DIVISION 15'!$A$15:$H$15,0),""),IFNA(MATCH($B8,'DIVISION 15'!$A$16:$H$16,0),""),IFNA(MATCH($B8,'DIVISION 15'!$A$17:$H$17,0),""),IFNA(MATCH($B8,'DIVISION 15'!$A$18:$H$18,0),""))=1,'DIVISION 15'!$A$1,SUM(IFNA(MATCH($B8,'DIVISION 15'!$A$2:$H$2,0),""),IFNA(MATCH($B8,'DIVISION 15'!$A$3:$H$3,0),""),IFNA(MATCH($B8,'DIVISION 15'!$A$4:$H$4,0),""),IFNA(MATCH($B8,'DIVISION 15'!$A$5:$H$5,0),""),IFNA(MATCH($B8,'DIVISION 15'!$A$6:$H$6,0),""),IFNA(MATCH($B8,'DIVISION 15'!$A$7:$H$7,0),""),IFNA(MATCH($B8,'DIVISION 15'!$A$8:$H$8,0),""),IFNA(MATCH($B8,'DIVISION 15'!$A$9:$H$9,0),""),IFNA(MATCH($B8,'DIVISION 15'!$A$10:$H$10,0),""),IFNA(MATCH($B8,'DIVISION 15'!$A$11:$H$11,0),""),IFNA(MATCH($B8,'DIVISION 15'!$A$12:$H$12,0),""),IFNA(MATCH($B8,'DIVISION 15'!$A$13:$H$13,0),""),IFNA(MATCH($B8,'DIVISION 15'!$A$14:$H$14,0),""),IFNA(MATCH($B8,'DIVISION 15'!$A$15:$H$15,0),""),IFNA(MATCH($B8,'DIVISION 15'!$A$16:$H$16,0),""),IFNA(MATCH($B8,'DIVISION 15'!$A$17:$H$17,0),""),IFNA(MATCH($B8,'DIVISION 15'!$A$18:$H$18,0),""))=2,'DIVISION 15'!$B$1,SUM(IFNA(MATCH($B8,'DIVISION 15'!$A$2:$H$2,0),""),IFNA(MATCH($B8,'DIVISION 15'!$A$3:$H$3,0),""),IFNA(MATCH($B8,'DIVISION 15'!$A$4:$H$4,0),""),IFNA(MATCH($B8,'DIVISION 15'!$A$5:$H$5,0),""),IFNA(MATCH($B8,'DIVISION 15'!$A$6:$H$6,0),""),IFNA(MATCH($B8,'DIVISION 15'!$A$7:$H$7,0),""),IFNA(MATCH($B8,'DIVISION 15'!$A$8:$H$8,0),""),IFNA(MATCH($B8,'DIVISION 15'!$A$9:$H$9,0),""),IFNA(MATCH($B8,'DIVISION 15'!$A$10:$H$10,0),""),IFNA(MATCH($B8,'DIVISION 15'!$A$11:$H$11,0),""),IFNA(MATCH($B8,'DIVISION 15'!$A$12:$H$12,0),""),IFNA(MATCH($B8,'DIVISION 15'!$A$13:$H$13,0),""),IFNA(MATCH($B8,'DIVISION 15'!$A$14:$H$14,0),""),IFNA(MATCH($B8,'DIVISION 15'!$A$15:$H$15,0),""),IFNA(MATCH($B8,'DIVISION 15'!$A$16:$H$16,0),""),IFNA(MATCH($B8,'DIVISION 15'!$A$17:$H$17,0),""),IFNA(MATCH($B8,'DIVISION 15'!$A$18:$H$18,0),""))=3,'DIVISION 15'!$C$1,SUM(IFNA(MATCH($B8,'DIVISION 15'!$A$2:$H$2,0),""),IFNA(MATCH($B8,'DIVISION 15'!$A$3:$H$3,0),""),IFNA(MATCH($B8,'DIVISION 15'!$A$4:$H$4,0),""),IFNA(MATCH($B8,'DIVISION 15'!$A$5:$H$5,0),""),IFNA(MATCH($B8,'DIVISION 15'!$A$6:$H$6,0),""),IFNA(MATCH($B8,'DIVISION 15'!$A$7:$H$7,0),""),IFNA(MATCH($B8,'DIVISION 15'!$A$8:$H$8,0),""),IFNA(MATCH($B8,'DIVISION 15'!$A$9:$H$9,0),""),IFNA(MATCH($B8,'DIVISION 15'!$A$10:$H$10,0),""),IFNA(MATCH($B8,'DIVISION 15'!$A$11:$H$11,0),""),IFNA(MATCH($B8,'DIVISION 15'!$A$12:$H$12,0),""),IFNA(MATCH($B8,'DIVISION 15'!$A$13:$H$13,0),""),IFNA(MATCH($B8,'DIVISION 15'!$A$14:$H$14,0),""),IFNA(MATCH($B8,'DIVISION 15'!$A$15:$H$15,0),""),IFNA(MATCH($B8,'DIVISION 15'!$A$16:$H$16,0),""),IFNA(MATCH($B8,'DIVISION 15'!$A$17:$H$17,0),""),IFNA(MATCH($B8,'DIVISION 15'!$A$18:$H$18,0),""))=4,'DIVISION 15'!$D$1,SUM(IFNA(MATCH($B8,'DIVISION 15'!$A$2:$H$2,0),""),IFNA(MATCH($B8,'DIVISION 15'!$A$3:$H$3,0),""),IFNA(MATCH($B8,'DIVISION 15'!$A$4:$H$4,0),""),IFNA(MATCH($B8,'DIVISION 15'!$A$5:$H$5,0),""),IFNA(MATCH($B8,'DIVISION 15'!$A$6:$H$6,0),""),IFNA(MATCH($B8,'DIVISION 15'!$A$7:$H$7,0),""),IFNA(MATCH($B8,'DIVISION 15'!$A$8:$H$8,0),""),IFNA(MATCH($B8,'DIVISION 15'!$A$9:$H$9,0),""),IFNA(MATCH($B8,'DIVISION 15'!$A$10:$H$10,0),""),IFNA(MATCH($B8,'DIVISION 15'!$A$11:$H$11,0),""),IFNA(MATCH($B8,'DIVISION 15'!$A$12:$H$12,0),""),IFNA(MATCH($B8,'DIVISION 15'!$A$13:$H$13,0),""),IFNA(MATCH($B8,'DIVISION 15'!$A$14:$H$14,0),""),IFNA(MATCH($B8,'DIVISION 15'!$A$15:$H$15,0),""),IFNA(MATCH($B8,'DIVISION 15'!$A$16:$H$16,0),""),IFNA(MATCH($B8,'DIVISION 15'!$A$17:$H$17,0),""),IFNA(MATCH($B8,'DIVISION 15'!$A$18:$H$18,0),""))=5,'DIVISION 15'!$E$1,SUM(IFNA(MATCH($B8,'DIVISION 15'!$A$2:$H$2,0),""),IFNA(MATCH($B8,'DIVISION 15'!$A$3:$H$3,0),""),IFNA(MATCH($B8,'DIVISION 15'!$A$4:$H$4,0),""),IFNA(MATCH($B8,'DIVISION 15'!$A$5:$H$5,0),""),IFNA(MATCH($B8,'DIVISION 15'!$A$6:$H$6,0),""),IFNA(MATCH($B8,'DIVISION 15'!$A$7:$H$7,0),""),IFNA(MATCH($B8,'DIVISION 15'!$A$8:$H$8,0),""),IFNA(MATCH($B8,'DIVISION 15'!$A$9:$H$9,0),""),IFNA(MATCH($B8,'DIVISION 15'!$A$10:$H$10,0),""),IFNA(MATCH($B8,'DIVISION 15'!$A$11:$H$11,0),""),IFNA(MATCH($B8,'DIVISION 15'!$A$12:$H$12,0),""),IFNA(MATCH($B8,'DIVISION 15'!$A$13:$H$13,0),""),IFNA(MATCH($B8,'DIVISION 15'!$A$14:$H$14,0),""),IFNA(MATCH($B8,'DIVISION 15'!$A$15:$H$15,0),""),IFNA(MATCH($B8,'DIVISION 15'!$A$16:$H$16,0),""),IFNA(MATCH($B8,'DIVISION 15'!$A$17:$H$17,0),""),IFNA(MATCH($B8,'DIVISION 15'!$A$18:$H$18,0),""))=6,'DIVISION 15'!$F$1,SUM(IFNA(MATCH($B8,'DIVISION 15'!$A$2:$H$2,0),""),IFNA(MATCH($B8,'DIVISION 15'!$A$3:$H$3,0),""),IFNA(MATCH($B8,'DIVISION 15'!$A$4:$H$4,0),""),IFNA(MATCH($B8,'DIVISION 15'!$A$5:$H$5,0),""),IFNA(MATCH($B8,'DIVISION 15'!$A$6:$H$6,0),""),IFNA(MATCH($B8,'DIVISION 15'!$A$7:$H$7,0),""),IFNA(MATCH($B8,'DIVISION 15'!$A$8:$H$8,0),""),IFNA(MATCH($B8,'DIVISION 15'!$A$9:$H$9,0),""),IFNA(MATCH($B8,'DIVISION 15'!$A$10:$H$10,0),""),IFNA(MATCH($B8,'DIVISION 15'!$A$11:$H$11,0),""),IFNA(MATCH($B8,'DIVISION 15'!$A$12:$H$12,0),""),IFNA(MATCH($B8,'DIVISION 15'!$A$13:$H$13,0),""),IFNA(MATCH($B8,'DIVISION 15'!$A$14:$H$14,0),""),IFNA(MATCH($B8,'DIVISION 15'!$A$15:$H$15,0),""),IFNA(MATCH($B8,'DIVISION 15'!$A$16:$H$16,0),""),IFNA(MATCH($B8,'DIVISION 15'!$A$17:$H$17,0),""),IFNA(MATCH($B8,'DIVISION 15'!$A$18:$H$18,0),""))=7,'DIVISION 15'!$G$1,SUM(IFNA(MATCH($B8,'DIVISION 15'!$A$2:$H$2,0),""),IFNA(MATCH($B8,'DIVISION 15'!$A$3:$H$3,0),""),IFNA(MATCH($B8,'DIVISION 15'!$A$4:$H$4,0),""),IFNA(MATCH($B8,'DIVISION 15'!$A$5:$H$5,0),""),IFNA(MATCH($B8,'DIVISION 15'!$A$6:$H$6,0),""),IFNA(MATCH($B8,'DIVISION 15'!$A$7:$H$7,0),""),IFNA(MATCH($B8,'DIVISION 15'!$A$8:$H$8,0),""),IFNA(MATCH($B8,'DIVISION 15'!$A$9:$H$9,0),""),IFNA(MATCH($B8,'DIVISION 15'!$A$10:$H$10,0),""),IFNA(MATCH($B8,'DIVISION 15'!$A$11:$H$11,0),""),IFNA(MATCH($B8,'DIVISION 15'!$A$12:$H$12,0),""),IFNA(MATCH($B8,'DIVISION 15'!$A$13:$H$13,0),""),IFNA(MATCH($B8,'DIVISION 15'!$A$14:$H$14,0),""),IFNA(MATCH($B8,'DIVISION 15'!$A$15:$H$15,0),""),IFNA(MATCH($B8,'DIVISION 15'!$A$16:$H$16,0),""),IFNA(MATCH($B8,'DIVISION 15'!$A$17:$H$17,0),""),IFNA(MATCH($B8,'DIVISION 15'!$A$18:$H$18,0),""))=8,'DIVISION 15'!$H$1) -> MARTO | U8: =T8&COUNTIF($T$1:T8,T8) -> MARTO2 | V8: =SUMIF(AsistenciaViewJetAdmin!$A$3:$A$101,A8,AsistenciaViewJetAdmin!$C$3:$C$101)/(COUNTIF(AsistenciaViewJetAdmin!$D$102:V$102,">0")+COUNTIF(ActividadesEspeciales!$D$102:V$102,">0"))*100 -> 71.808511
A9: 150 | B9: Tobias Karpeliowski | C9: 11901 | D9: 26/10/2009 | E9: 49926649 | F9: ycreiener@ort.edu.ar | G9: 1170037804 | H9: yanina creiner | I9: ycreiner@ort.edu.ar | J9: 1168668577 | K9: laureano karpeliowski | L9: crtiter1@hotmail.com | M9: 1149974001 | N9: ort | O9: no | P9: futbol | Q9: Nedarim | R9: Sin restricciones | S9: NARANJA | T9: =IFS(SUM(IFNA(MATCH($B9,'DIVISION 15'!$A$2:$H$2,0),""),IFNA(MATCH($B9,'DIVISION 15'!$A$3:$H$3,0),""),IFNA(MATCH($B9,'DIVISION 15'!$A$4:$H$4,0),""),IFNA(MATCH($B9,'DIVISION 15'!$A$5:$H$5,0),""),IFNA(MATCH($B9,'DIVISION 15'!$A$6:$H$6,0),""),IFNA(MATCH($B9,'DIVISION 15'!$A$7:$H$7,0),""),IFNA(MATCH($B9,'DIVISION 15'!$A$8:$H$8,0),""),IFNA(MATCH($B9,'DIVISION 15'!$A$9:$H$9,0),""),IFNA(MATCH($B9,'DIVISION 15'!$A$10:$H$10,0),""),IFNA(MATCH($B9,'DIVISION 15'!$A$11:$H$11,0),""),IFNA(MATCH($B9,'DIVISION 15'!$A$12:$H$12,0),""),IFNA(MATCH($B9,'DIVISION 15'!$A$13:$H$13,0),""),IFNA(MATCH($B9,'DIVISION 15'!$A$14:$H$14,0),""),IFNA(MATCH($B9,'DIVISION 15'!$A$15:$H$15,0),""),IFNA(MATCH($B9,'DIVISION 15'!$A$16:$H$16,0),""),IFNA(MATCH($B9,'DIVISION 15'!$A$17:$H$17,0),""),IFNA(MATCH($B9,'DIVISION 15'!$A$18:$H$18,0),""))=1,'DIVISION 15'!$A$1,SUM(IFNA(MATCH($B9,'DIVISION 15'!$A$2:$H$2,0),""),IFNA(MATCH($B9,'DIVISION 15'!$A$3:$H$3,0),""),IFNA(MATCH($B9,'DIVISION 15'!$A$4:$H$4,0),""),IFNA(MATCH($B9,'DIVISION 15'!$A$5:$H$5,0),""),IFNA(MATCH($B9,'DIVISION 15'!$A$6:$H$6,0),""),IFNA(MATCH($B9,'DIVISION 15'!$A$7:$H$7,0),""),IFNA(MATCH($B9,'DIVISION 15'!$A$8:$H$8,0),""),IFNA(MATCH($B9,'DIVISION 15'!$A$9:$H$9,0),""),IFNA(MATCH($B9,'DIVISION 15'!$A$10:$H$10,0),""),IFNA(MATCH($B9,'DIVISION 15'!$A$11:$H$11,0),""),IFNA(MATCH($B9,'DIVISION 15'!$A$12:$H$12,0),""),IFNA(MATCH($B9,'DIVISION 15'!$A$13:$H$13,0),""),IFNA(MATCH($B9,'DIVISION 15'!$A$14:$H$14,0),""),IFNA(MATCH($B9,'DIVISION 15'!$A$15:$H$15,0),""),IFNA(MATCH($B9,'DIVISION 15'!$A$16:$H$16,0),""),IFNA(MATCH($B9,'DIVISION 15'!$A$17:$H$17,0),""),IFNA(MATCH($B9,'DIVISION 15'!$A$18:$H$18,0),""))=2,'DIVISION 15'!$B$1,SUM(IFNA(MATCH($B9,'DIVISION 15'!$A$2:$H$2,0),""),IFNA(MATCH($B9,'DIVISION 15'!$A$3:$H$3,0),""),IFNA(MATCH($B9,'DIVISION 15'!$A$4:$H$4,0),""),IFNA(MATCH($B9,'DIVISION 15'!$A$5:$H$5,0),""),IFNA(MATCH($B9,'DIVISION 15'!$A$6:$H$6,0),""),IFNA(MATCH($B9,'DIVISION 15'!$A$7:$H$7,0),""),IFNA(MATCH($B9,'DIVISION 15'!$A$8:$H$8,0),""),IFNA(MATCH($B9,'DIVISION 15'!$A$9:$H$9,0),""),IFNA(MATCH($B9,'DIVISION 15'!$A$10:$H$10,0),""),IFNA(MATCH($B9,'DIVISION 15'!$A$11:$H$11,0),""),IFNA(MATCH($B9,'DIVISION 15'!$A$12:$H$12,0),""),IFNA(MATCH($B9,'DIVISION 15'!$A$13:$H$13,0),""),IFNA(MATCH($B9,'DIVISION 15'!$A$14:$H$14,0),""),IFNA(MATCH($B9,'DIVISION 15'!$A$15:$H$15,0),""),IFNA(MATCH($B9,'DIVISION 15'!$A$16:$H$16,0),""),IFNA(MATCH($B9,'DIVISION 15'!$A$17:$H$17,0),""),IFNA(MATCH($B9,'DIVISION 15'!$A$18:$H$18,0),""))=3,'DIVISION 15'!$C$1,SUM(IFNA(MATCH($B9,'DIVISION 15'!$A$2:$H$2,0),""),IFNA(MATCH($B9,'DIVISION 15'!$A$3:$H$3,0),""),IFNA(MATCH($B9,'DIVISION 15'!$A$4:$H$4,0),""),IFNA(MATCH($B9,'DIVISION 15'!$A$5:$H$5,0),""),IFNA(MATCH($B9,'DIVISION 15'!$A$6:$H$6,0),""),IFNA(MATCH($B9,'DIVISION 15'!$A$7:$H$7,0),""),IFNA(MATCH($B9,'DIVISION 15'!$A$8:$H$8,0),""),IFNA(MATCH($B9,'DIVISION 15'!$A$9:$H$9,0),""),IFNA(MATCH($B9,'DIVISION 15'!$A$10:$H$10,0),""),IFNA(MATCH($B9,'DIVISION 15'!$A$11:$H$11,0),""),IFNA(MATCH($B9,'DIVISION 15'!$A$12:$H$12,0),""),IFNA(MATCH($B9,'DIVISION 15'!$A$13:$H$13,0),""),IFNA(MATCH($B9,'DIVISION 15'!$A$14:$H$14,0),""),IFNA(MATCH($B9,'DIVISION 15'!$A$15:$H$15,0),""),IFNA(MATCH($B9,'DIVISION 15'!$A$16:$H$16,0),""),IFNA(MATCH($B9,'DIVISION 15'!$A$17:$H$17,0),""),IFNA(MATCH($B9,'DIVISION 15'!$A$18:$H$18,0),""))=4,'DIVISION 15'!$D$1,SUM(IFNA(MATCH($B9,'DIVISION 15'!$A$2:$H$2,0),""),IFNA(MATCH($B9,'DIVISION 15'!$A$3:$H$3,0),""),IFNA(MATCH($B9,'DIVISION 15'!$A$4:$H$4,0),""),IFNA(MATCH($B9,'DIVISION 15'!$A$5:$H$5,0),""),IFNA(MATCH($B9,'DIVISION 15'!$A$6:$H$6,0),""),IFNA(MATCH($B9,'DIVISION 15'!$A$7:$H$7,0),""),IFNA(MATCH($B9,'DIVISION 15'!$A$8:$H$8,0),""),IFNA(MATCH($B9,'DIVISION 15'!$A$9:$H$9,0),""),IFNA(MATCH($B9,'DIVISION 15'!$A$10:$H$10,0),""),IFNA(MATCH($B9,'DIVISION 15'!$A$11:$H$11,0),""),IFNA(MATCH($B9,'DIVISION 15'!$A$12:$H$12,0),""),IFNA(MATCH($B9,'DIVISION 15'!$A$13:$H$13,0),""),IFNA(MATCH($B9,'DIVISION 15'!$A$14:$H$14,0),""),IFNA(MATCH($B9,'DIVISION 15'!$A$15:$H$15,0),""),IFNA(MATCH($B9,'DIVISION 15'!$A$16:$H$16,0),""),IFNA(MATCH($B9,'DIVISION 15'!$A$17:$H$17,0),""),IFNA(MATCH($B9,'DIVISION 15'!$A$18:$H$18,0),""))=5,'DIVISION 15'!$E$1,SUM(IFNA(MATCH($B9,'DIVISION 15'!$A$2:$H$2,0),""),IFNA(MATCH($B9,'DIVISION 15'!$A$3:$H$3,0),""),IFNA(MATCH($B9,'DIVISION 15'!$A$4:$H$4,0),""),IFNA(MATCH($B9,'DIVISION 15'!$A$5:$H$5,0),""),IFNA(MATCH($B9,'DIVISION 15'!$A$6:$H$6,0),""),IFNA(MATCH($B9,'DIVISION 15'!$A$7:$H$7,0),""),IFNA(MATCH($B9,'DIVISION 15'!$A$8:$H$8,0),""),IFNA(MATCH($B9,'DIVISION 15'!$A$9:$H$9,0),""),IFNA(MATCH($B9,'DIVISION 15'!$A$10:$H$10,0),""),IFNA(MATCH($B9,'DIVISION 15'!$A$11:$H$11,0),""),IFNA(MATCH($B9,'DIVISION 15'!$A$12:$H$12,0),""),IFNA(MATCH($B9,'DIVISION 15'!$A$13:$H$13,0),""),IFNA(MATCH($B9,'DIVISION 15'!$A$14:$H$14,0),""),IFNA(MATCH($B9,'DIVISION 15'!$A$15:$H$15,0),""),IFNA(MATCH($B9,'DIVISION 15'!$A$16:$H$16,0),""),IFNA(MATCH($B9,'DIVISION 15'!$A$17:$H$17,0),""),IFNA(MATCH($B9,'DIVISION 15'!$A$18:$H$18,0),""))=6,'DIVISION 15'!$F$1,SUM(IFNA(MATCH($B9,'DIVISION 15'!$A$2:$H$2,0),""),IFNA(MATCH($B9,'DIVISION 15'!$A$3:$H$3,0),""),IFNA(MATCH($B9,'DIVISION 15'!$A$4:$H$4,0),""),IFNA(MATCH($B9,'DIVISION 15'!$A$5:$H$5,0),""),IFNA(MATCH($B9,'DIVISION 15'!$A$6:$H$6,0),""),IFNA(MATCH($B9,'DIVISION 15'!$A$7:$H$7,0),""),IFNA(MATCH($B9,'DIVISION 15'!$A$8:$H$8,0),""),IFNA(MATCH($B9,'DIVISION 15'!$A$9:$H$9,0),""),IFNA(MATCH($B9,'DIVISION 15'!$A$10:$H$10,0),""),IFNA(MATCH($B9,'DIVISION 15'!$A$11:$H$11,0),""),IFNA(MATCH($B9,'DIVISION 15'!$A$12:$H$12,0),""),IFNA(MATCH($B9,'DIVISION 15'!$A$13:$H$13,0),""),IFNA(MATCH($B9,'DIVISION 15'!$A$14:$H$14,0),""),IFNA(MATCH($B9,'DIVISION 15'!$A$15:$H$15,0),""),IFNA(MATCH($B9,'DIVISION 15'!$A$16:$H$16,0),""),IFNA(MATCH($B9,'DIVISION 15'!$A$17:$H$17,0),""),IFNA(MATCH($B9,'DIVISION 15'!$A$18:$H$18,0),""))=7,'DIVISION 15'!$G$1,SUM(IFNA(MATCH($B9,'DIVISION 15'!$A$2:$H$2,0),""),IFNA(MATCH($B9,'DIVISION 15'!$A$3:$H$3,0),""),IFNA(MATCH($B9,'DIVISION 15'!$A$4:$H$4,0),""),IFNA(MATCH($B9,'DIVISION 15'!$A$5:$H$5,0),""),IFNA(MATCH($B9,'DIVISION 15'!$A$6:$H$6,0),""),IFNA(MATCH($B9,'DIVISION 15'!$A$7:$H$7,0),""),IFNA(MATCH($B9,'DIVISION 15'!$A$8:$H$8,0),""),IFNA(MATCH($B9,'DIVISION 15'!$A$9:$H$9,0),""),IFNA(MATCH($B9,'DIVISION 15'!$A$10:$H$10,0),""),IFNA(MATCH($B9,'DIVISION 15'!$A$11:$H$11,0),""),IFNA(MATCH($B9,'DIVISION 15'!$A$12:$H$12,0),""),IFNA(MATCH($B9,'DIVISION 15'!$A$13:$H$13,0),""),IFNA(MATCH($B9,'DIVISION 15'!$A$14:$H$14,0),""),IFNA(MATCH($B9,'DIVISION 15'!$A$15:$H$15,0),""),IFNA(MATCH($B9,'DIVISION 15'!$A$16:$H$16,0),""),IFNA(MATCH($B9,'DIVISION 15'!$A$17:$H$17,0),""),IFNA(MATCH($B9,'DIVISION 15'!$A$18:$H$18,0),""))=8,'DIVISION 15'!$H$1) -> SOFI | U9: =T9&COUNTIF($T$1:T9,T9) -> SOFI1 | V9: =SUMIF(AsistenciaViewJetAdmin!$A$3:$A$101,A9,AsistenciaViewJetAdmin!$C$3:$C$101)/(COUNTIF(AsistenciaViewJetAdmin!$D$102:V$102,">0")+COUNTIF(ActividadesEspeciales!$D$102:V$102,">0"))*100 -> 39.893617
